Workbook

Sheet BS 8490 Calculations
C2: Rainfall Calculations | D2: (BS EN 12056-3:2000)
C4: Rainfall Intensity (l/s/m^2) | D4: 0.02 | F4: The rainfall calculations convert the characteristic rianfall intensity supplied in the brief to a final design value
C5: Reduced Climate Change Allowance | D5: 0.15 | F5: This is inflated by the upper 15% of the total 45% government climate change allowance from section 6.1.5
C6: Factor of safety | D6: 0.1 | F6: 10% safety factor as mandated by BS 8490
C7: Design Intensity (l/s/m^2) | D7: =D4*(1+D5)*(1+D6) -> 0.0253
C10: Roof area and volume calculations | E10: (BS EN 12056)
C12: Roof Section: | D12: 1 | L12: Roof Section: | M12: 2 | R12: Roof Section: | S12: 3 | T12: (Combined atrium and greenroof) | X12: Roof Section: | Y12: 4
C13: Drainage method: | D13: 2 stage siphon | L13: Drainage method: | M13: 2 stage siphon | R13: Drainage method: | S13: Single stage siphon | X13: Drainage method: | Y13: Single stage siphon
C15: Roof area (m^2) | D15: 1062.7 | L15: Roof area (m^2) | M15: 1074.1 | R15: Roof area (m^2) | S15: 470 | X15: Roof area (m^2) | Y15: 385.8
C16: Total flow (m^3/s) | D16: =D15*D7/1000 -> 0.02688631 | E16: 126.5% calculated in section 6.1.5 | L16: Total flow (m^3/s) | M16: =M15*D7/1000 -> 0.02717473 | R16: Total flow (m^3/s) | S16: =S15*D7/1000 -> 0.011891 | X16: Total flow (m^3/s) | Y16: =Y15*D7/1000 -> 0.00976074
C19: Gravitational overflow calculations | F19: (BS EN 12056)
C21: Overflow volume (m^3/s) | D21: =(D16*159.5/126.5)-D16 -> 0.00701382 | E21: 33% (6.1.5) to ensure safe operation in high volume events | L21: Overflow volume (m^3/s) | M21: =(M16*159.5/126.5)-M16 -> 0.00708906 | R21: Overflow volume (m^3/s) | S21: =(S16*159.5/126.5)-S16 -> 0.003102 | X21: Overflow volume (m^3/s) | Y21: =(Y16*159.5/126.5)-Y16 -> 0.00254628
C22: Appropriate overflow pipe D (m) | D22: 0.095 | E22: Calculated using table 8 (6.1.1 - BS EN 12056) with filling degree 0.33 | L22: Appropriate overflow pipe D | M22: 0.095 | R22: Appropriate overflow pipe D | S22: 0.065 | X22: Appropriate overflow pipe D | Y22: 0.06
C25: Pipe calculations | D25: (BS 8490)
B27: BS 8490 | C27: Outlets | D27: 3 | L27: Outlets | M27: 3 | R27: Outlets | S27: 2 | X27: Outlets | Y27: 2
B28: step:
B29: a) | C29: Area/outlet (m) | D29: =D15/D27 -> 354.23333 | L29: Area/outlet (m) | M29: =M15/M27 -> 358.03333 | R29: Area/outlet (m) | S29: =S15/S27 -> 235 | X29: Area/outlet (m) | Y29: =Y15/Y27 -> 192.9
C30: Inflow/outlet (m^3/s) | D30: =D16/D27 -> 0.0089621033 | L30: Inflow/outlet (m^3/s) | M30: =M16/M27 -> 0.0090582433 | R30: Inflow/outlet (m^3/s) | S30: =S16/2 -> 0.0059455 | X30: Inflow/outlet (m^3/s) | Y30: =Y16/Y27 -> 0.00488037
C31: Gutter height (m) | D31: 20 | F31: Level of inner eave (bottom of roof slope) | L31: Gutter height (m) | M31: 16 | R31: Gutter height (m) | S31: 12 | X31: Gutter height (m) | Y31: 8
C32: Discharge height (m) | L32: Discharge height (m) | R32: Discharge height (m) | X32: Discharge height (m)
C34: Transfer Gulley -> Downpipe Outlet | F34: BS 8490 specifies working upwards from the lowest point (downpipe outlet) | L34: Transfer Gulley -> Downpipe Outlet | R34: Collector Pipe -> Downpipe Outlet | X34: Collector Pipe -> Downpipe Outlet
B35: BS 8490 | K35: BS 8490 | Q35: BS 8490 | W35: BS 8490
B36: step: | C36: Downpipe Outlet (4) | K36: step: | L36: Downpipe Outlet (3) | Q36: step: | R36: Downpipe Outlet (3) | W36: step: | X36: Downpipe Outlet (3)
B37: b) | C37: Diamter (m) | D37: 0.11 | K37: b) | L37: Diamter (m) | M37: 0.11 | Q37: b) | R37: Diamter (m) | S37: 0.075 | W37: b) | X37: Diamter (m) | Y37: 0.075
C38: Area (m^2) | D38: =PI()*((D37/2)^2) -> 0.0095033178 | L38: Area (m^2) | M38: =PI()*((M37/2)^2) -> 0.0095033178 | R38: Area (m^2) | S38: =PI()*((S37/2)^2) -> 0.0044178647 | X38: Area (m^2) | Y38: =PI()*((Y37/2)^2) -> 0.0044178647
C39: Q (m^3/s) | D39: =D15*D7/1000 -> 0.02688631 | F39: The Q value considers the total flow of all the outlets which are combined in the collector pipe | L39: Q (m^3/s) | M39: =M15*D7/1000 -> 0.02717473 | R39: Q (m^3/s) | S39: =S15*D7/1000 -> 0.011891 | X39: Q (m^3/s) | Y39: =Y15*D7/1000 -> 0.00976074
C40: V (m/s) | D40: =D39/D38 -> 2.8291498 | L40: V (m/s) | M40: =M39/M38 -> 2.8594992 | R40: V (m/s) | S40: =S39/S38 -> 2.6915718 | X40: V (m/s) | Y40: =Y39/Y38 -> 2.2093796
C41: Z (m) | D41: 2 | L41: Z (m) | M41: 2 | R41: Z (m) | S41: 2 | X41: Z (m) | Y41: 2
B42: c) | C42: h (outlet) (m) | D42: 0 | F42: Pressure head at the outlet is 0 (atmospheric pressure) | K42: c) | L42: h (m) | M42: 0 | Q42: c) | R42: h (m) | S42: 0 | W42: c) | X42: h (m) | Y42: 0
C44: Transfer Gulley Outlet (3) | L44: Transfer Gulley Outlet (3) | R44: Collector Pipe Outlet (2) | X44: Collector Pipe Outlet (2)
C45: Diameter (m) | D45: =D37 -> 0.11 | F45: As the continuity equation says Q must be constant, we can adjust the transfer gulley outlet to prevent insufficient or excessive flow velocity | L45: Diameter (m) | M45: =M37 -> 0.11 | R45: Diameter (m) | S45: =S37 -> 0.075 | X45: Diameter (m) | Y45: =Y37 -> 0.075
C46: Area (m^2) | D46: =PI()*((D45/2)^2) -> 0.0095033178 | L46: Area (m^2) | M46: =PI()*((M45/2)^2) -> 0.0095033178 | R46: Area (m^2) | S46: =PI()*((S45/2)^2) -> 0.0044178647 | X46: Area (m^2) | Y46: =PI()*((Y45/2)^2) -> 0.0044178647
C47: Q (m^3/s) | D47: =D39 -> 0.02688631 | L47: Q (m^3/s) | M47: =M39 -> 0.02717473 | R47: Q (m^3/s) | S47: =S39 -> 0.011891 | X47: Q (m^3/s) | Y47: =Y39 -> 0.00976074
C48: V (m/s) | D48: =D47/D46 -> 2.8291498 | L48: V (m/s) | M48: =M47/M46 -> 2.8594992 | R48: V (m/s) | S48: =S47/S46 -> 2.6915718 | X48: V (m/s) | Y48: =Y47/Y46 -> 2.2093796
C49: z (m) | D49: 11.5 | L49: z (m) | M49: 8 | R49: z (m) | S49: 10 | X49: z (m) | Y49: 10
B51: d) | C51: Δz (3-2) (m) | D51: =D49-D41 -> 9.5 | K51: d) | L51: Δz (3-2) (m) | M51: =M49-M41 -> 6 | Q51: d) | R51: Δz (3-2) (m) | S51: =S49-S41 -> 8 | W51: d) | X51: Δz (3-2) (m) | Y51: =Y49-Y41 -> 8
C53: k(s) (m) | D53: 0.00015 | F53: 0.15mm is used for HDPE as the pipe roughness as specified in BS 8490 | L53: k(s) (m) | M53: 0.00015 | R53: k(s) (m) | S53: 0.00015 | X53: k(s) (m) | Y53: 0.00015
C54: Re | D54: =D40*D37/(1*(10^(-6))) -> 311206.48 | L54: Re | M54: =M40*M37/(1*(10^(-6))) -> 314544.92 | R54: Re | S54: =S40*S37/(1*(10^(-6))) -> 201867.89 | X54: Re | Y54: =Y40*Y37/(1*(10^(-6))) -> 165703.47
C55: λ | D55: =1/((-2*LOG10(((D53/D37)/3.7)) + (((5.1286/(D54^0.89)))))^2) -> 0.021205901 | L55: λ | M55: =1/((-2*LOG10(((M53/M37)/3.7)) + (((5.1286/(M54^0.89)))))^2) -> 0.021205905 | R55: λ | S55: =1/((-2*LOG10(((S53/S37)/3.7)) + (((5.1286/(S54^0.89)))))^2) -> 0.023419798 | X55: λ | Y55: =1/((-2*LOG10(((Y53/Y37)/3.7)) + (((5.1286/(Y54^0.89)))))^2) -> 0.023419664
C56: L | D56: 9.5 | L56: L | M56: 9.5 | R56: L | S56: 9.5 | X56: L | Y56: 9.5
...

Sheet System Summary Statistics
C3: Roof section | D3: Single/Dual Siphon System | E3: Tailpipe Outlet V (m/s) | F3: Tail/Collector Pipe Pressure Head (m) | G3: Primary downpipe V (m/s) (1) | H3: Transfer Gulley Pressure Head (m) | I3: Secondary Downpipe V (m/s) (2)
C4: 1 | D4: Dual | E4: ='BS 8490 Calculations'!D119 -> 2.0286052 | F4: ='BS 8490 Calculations'!D108 -> -1.7709066 | G4: ='BS 8490 Calculations'!D87 -> 2.8291498 | H4: ='BS 8490 Calculations'!D108 -> -1.7709066 | I4: ='BS 8490 Calculations'!D48 -> 2.8291498 | L4: S
C5: 2 | D5: Dual | E5: ='BS 8490 Calculations'!M119 -> 2.0503669 | F5: ='BS 8490 Calculations'!M108 -> -5.7497877 | G5: ='BS 8490 Calculations'!M87 -> 2.8594992 | H5: ='BS 8490 Calculations'!M108 -> -5.7497877 | I5: ='BS 8490 Calculations'!M40 -> 2.8594992
C6: 3 | D6: Single | E6: ='BS 8490 Calculations'!S79 -> 1.3457859 | F6: ='BS 8490 Calculations'!S70 -> -6.3507708 | G6: ='BS 8490 Calculations'!S48 -> 2.6915718 | H6: n/a | I6: n/a
C7: 4 | D7: Single | E7: ='BS 8490 Calculations'!Y79 -> 1.1046898 | F7: ='BS 8490 Calculations'!Y70 -> -6.8887594 | G7: ='BS 8490 Calculations'!Y40 -> 2.2093796 | H7: n/a | I7: n/a
D8: BS 8490 Limit: | E8: >1m/s | F8: >-8.8m | G8: >2.2m/s | H8: >-8.8m | I8: >2.2m/s
M24: SS
