Workbook

Sheet Summary
A1: Constants | D1: Energy IN | E1: =E2 -> 280622.35 | G1: Energy OUT | H1: =SUM(H2:H13) -> 394676
A2: Realistic best | B2: =E1-Savings!D9 -> 43141.875 | D2: Solar | E2: =OVERENERGy!H20 -> 280622.35 | G2: Lights | H2: =Lighting!H7 -> 51048 | I2: =H2/H$1 -> 0.12934154
A3: Realistic worst | B3: =E1-Savings!E9 -> -93245.845 | G3: Desktops | H3: =Comps!F4 -> 34080 | I3: =H3/H$1 -> 0.086349309
A4: Daily Hours (whole Building | B4: 12 | G4: Lifts | H4: =Other!E2 -> 5475 | I4: =H4/H$1 -> 0.013872138
A5: Daily Hours (Office Computers) | B5: 8 | G5: Cooking | H5: =SUM('Cooking '!E2:E6) -> 51350 | I5: =H5/H$1 -> 0.13010672
A6: Working Days | B6: 300 | G6: Heating | H6: =36837+41678 -> 78515 | I6: =H6/H$1 -> 0.19893533
A7: Carbon Emmissions Best Case Energy Savings (Tonnes of CO2) | B7: =(IF(B2<0, B2*0.233*(-1), 0))/1000 -> 0 | G7: Café | H7: 25000 | I7: =H7/H$1 -> 0.063343097
A8: Carbon Emmissions Worst Case Energy Savings (Tonnes of CO2) | B8: =(IF(B3<0, B3*0.233*(-1), 0))/1000 -> 21.726282 | G8: Pump | H8: =Other!E4 -> 14280 | I8: =H8/H$1 -> 0.036181577
A9: Carbon No Energy Savings (Tonnes of CO2) | B9: =((H1-E1)*0.233)/1000 -> 26.574499 | G9: Big Screens | H9: =Comps!F5 -> 10584 | I9: =H9/H$1 -> 0.026816933
A10: Carbon Emissions No Solar (Tonnes of CO2) | B10: =(H1*0.233)/1000 -> 91.959508 | G10: Laptops | H10: =Comps!F2 -> 95040 | I10: =H10/H$1 -> 0.24080512
A11: Energy Use covered by Solar Best Case | B11: =Summary!E1/Savings!D9 -> 1.1816649 | G11: Printers | H11: =Comps!F6 -> 5544 | I11: =H11/H$1 -> 0.014046965
A12: Energy Use covered by Solar Worst Case | B12: =Summary!E1/Savings!E9 -> 0.75059167 | G12: Monitors | H12: =Comps!F3 -> 23760 | I12: =H12/H$1 -> 0.060201279
A13: Energy Use Covered Energy Savings | B13: =E2/H1 -> 0.71101956 | G13: Ventilation | I13: =H13/H$1 -> 0
G14: EV | H14: =Other!G5 -> 189000 | I14: =SUM(I2:I12) -> 1

Sheet 89100
A1: Energy Demand Type | B1: Percentage Energy Demand | C1: Energy Demand kWh/year
A2: Office Equipment | B2: =(Table1[[#This Row],[Energy Demand kWh/year]]/C$7) -> 0.4282196 | C2: =SUM(Comps!F2:F6) -> 169008
A3: Heating and Ventilation | B3: =(Table1[[#This Row],[Energy Demand kWh/year]]/C$7) -> 0.19893533 | C3: =Summary!H6 -> 78515
A4: Breakroom Equipment | B4: =(Table1[[#This Row],[Energy Demand kWh/year]]/C$7) -> 0.13010672 | C4: =SUM('Cooking '!E2:E6) -> 51350
A5: Lighting | B5: =(Table1[[#This Row],[Energy Demand kWh/year]]/C$7) -> 0.12934154 | C5: =Summary!H2 -> 51048
A6: Other | B6: =(Table1[[#This Row],[Energy Demand kWh/year]]/C$7) -> 0.11339681 | C6: =C7-SUM(C2:C5) -> 44755
A7: Total | B7: - | C7: =Summary!H1 -> 394676

Sheet Graphs
A1: Scenario Type | B1: Energy Use covered by Solar Energy (%) | D1: Scenario Type | E1: Carbon Emissions (Tonnes of CO2/Year) | F1: Trees required for offset
A2: Energy Savings Best Case | B2: =Summary!B11 -> 1.1816649 | D2: Best Case Energy Savings + Solar | E2: =TRUNC(Summary!B7) -> 0 | F2: =E2*50 -> 0 | G2: =ROUND(F2,0) -> 0
A3: Energy Savings Worst Case | B3: =Summary!B12 -> 0.75059167 | D3: Worst Case Energy Savings + Solar | E3: =ROUND(Summary!B8,1) -> 21.7 | F3: =E3*50 -> 1085 | G3: =ROUND(F3,0) -> 1085
A4: No Energy Savings | B4: =Summary!B13 -> 0.71101956 | D4: No Energy Savings + Solar | E4: =ROUND(Summary!B9,1) -> 26.6 | F4: =E4*50 -> 1330 | G4: =ROUND(F4,0) -> 1330
D5: Best Case Energy Savings | E5: =ROUND((Savings!D9*0.233)/1000,1) -> 55.3 | F5: =E5*50 -> 2765 | G5: =ROUND(F5,0) -> 2765
D6: Worst Case Energy Savings | E6: =ROUND(Savings!E9*0.233/1000,1) -> 87.1 | F6: =E6*50 -> 4355 | G6: =ROUND(F6,0) -> 4355
D7: No Energy Savings | E7: =ROUND(Summary!B10,1) -> 92 | F7: =E7*50 -> 4600 | G7: =ROUND(F7,0) -> 4600

Sheet Cooking 
A1: Type | B1: KWH | C1: KWH/Year | D1: amount | E1: Total energy for building
A2: Hot water dispenser | B2: 1.98 | C2: =B2*Summary!B6 -> 594 | D2: ='Per Room Fit Out'!R$7 -> 26 | E2: =D2*C2 -> 15444
A3: Fridge | B3: - | C3: 166 | D3: ='Per Room Fit Out'!R$7 -> 26 | E3: =D3*C3 -> 4316
A4: Water fount | B4: 0.65 | C4: =B4*Summary!B6 -> 195 | D4: ='Per Room Fit Out'!R$7 -> 26 | E4: =D4*C4 -> 5070
A5: Dishwasher | B5: 3 | C5: =B5*Summary!B6 -> 900 | D5: ='Per Room Fit Out'!R$7 -> 26 | E5: =D5*C5 -> 23400
A6: Microwave | B6: 0.4 | C6: =B6*Summary!B6 -> 120 | D6: ='Per Room Fit Out'!R$7 -> 26 | E6: =D6*C6 -> 3120
A12: Total Energy

Sheet Savings
A1: Energy saving Idea | B1: Max Energy Savings | C1: Min Energy savings | D1: Reductions Max | E1: Redcutions Min | F1: Realistic Best Case (KWH/Year) | G1: Realistic Worst Case (KW/m2/Day)
A2: Baseline | D2: =F2 -> 394676 | E2: =D2 -> 394676 | F2: =Summary!H1 -> 394676 | G2: =Summary!H1 -> 394676
A3: Roof Insulation | B3: =0.35*B17 -> 0.069627365 | C3: =0.1*B17 -> 0.019893533 | D3: =D$2*B3 -> 27480.25 | E3: =E$2*C3 -> 7851.5 | F3: =F2*0.65 -> 256539.4 | G3: =G2*0.9 -> 355208.4
A4: Automatic Lighting Best Case | B4: =0.35*B18 -> 0.045269538 | C4: =0.1*B18 -> 0.012934154 | D4: =D$2*B4 -> 17866.8 | E4: =E$2*C4 -> 5104.8 | F4: =F3*65% -> 166750.61 | G4: =G2*90% -> 355208.4
A5: Pipe work Insulation | B5: =0.35*B17 -> 0.069627365 | C5: =0.05*B17 -> 0.0099467665 | D5: =D$2*B5 -> 27480.25 | E5: =E$2*C5 -> 3925.75 | F5: =F4*0.65 -> 108387.9 | G5: =G6*0.95 -> 320575.58
A6: Boiler Sequence Controls | B6: =0.22*B17 -> 0.043765772 | C6: =0.05*B17 -> 0.0099467665 | D6: =D$2*B6 -> 17273.3 | E6: =E$2*C6 -> 3925.75 | F6: =F5*0.78 -> 84542.559 | G6: =G7*0.95 -> 337447.98
A7: Student Awareness | B7: 0.1 | C7: 0 | D7: =D$2*B7 -> 39467.6 | E7: =E$2*C7 -> 0 | F7: =F6*90% -> 76088.303 | G7: =G4*1 -> 355208.4
A8: Staff Awareness | B8: 0.07 | C8: 0 | D8: =D$2*B8 -> 27627.32 | E8: =E$2*C8 -> 0 | F8: =F7*0.93 -> 70762.122 | G8: =G7*1 -> 355208.4
A9: Final | B9: =SUM(B3:B8) -> 0.39829004 | C9: =SUM(C3:C8) -> 0.052721219 | D9: =D2-SUM(D3:D8) -> 237480.48 | E9: =E2-SUM(E3:E8) -> 373868.2 | F9: =F5 -> 108387.9 | G9: =G5 -> 320575.58
E10: =AVERAGE(D9:G9) -> 260078.04
A12: Constants
A13: Other | B13: =Summary!H1 -> 394676
A14: Heating | B14: =Summary!H6 -> 78515
A15: Lighting | B15: =Summary!H2 -> 51048
A16: Screens | B16: =Comps!F8 -> 163464
A17: Heating percent | B17: =B14/B13 -> 0.19893533
A18: Lighting percent | B18: =B15/B13 -> 0.12934154
A19: Screens percent | B19: =B16/B13 -> 0.41417264

Sheet Lighting
A1: Type of lighting | B1: LUX levels | C1: Lights per sq foot | D1: Cost per light | E1: Watts | F1: Electricity use per day (KJ) | G1: KWH/day per light | H1: KWH/Year building | I1: KWH/year per light | J1: Electricity use for building | K1: Cost per unit per day | L1: Electrical cost per day
A2: Overcast Daylight | B2: 1000 | C2: =750/B2 -> 0.75 | D2: 0
A3: Sunset/Sunrise | B3: 400 | C3: =750/B3 -> 1.875 | D3: 0 | F3: 0 | J3: 0
A4: Moonlight | B4: 1 | C4: =750/B4 -> 750 | D4: 0 | F4: 0 | J4: 0
A5: Overhead lights | B5: 3000 | C5: =750/B5 -> 0.25 | E5: 39 | F5: =(E5*8*60*60)/1000 -> 1123.2 | G5: =(E5*Summary!B$4)/1000 -> 0.468 | H5: =I5*'Per Room Fit Out'!R$2 -> 99543.6 | I5: =G5*Summary!B$6 -> 140.4 | J5: =F5*'Per Room Fit Out'!G2 -> 195436.8 | K5: 0.08 | L5: =K5*'Per Room Fit Out'!G2 -> 13.92
A6: Spotlight | B6: 1000 | C6: =750/B6 -> 0.75 | E6: 10 | F6: =(E6*8*60*60)/1000 -> 288 | G6: =(E6*Summary!B$4)/1000 -> 0.12 | H6: =I6*'Per Room Fit Out'!R$2 -> 25524 | I6: =G6*Summary!B$6 -> 36 | J6: =F6*'Per Room Fit Out'!G3 -> 0 | K6: 0.02
A7: LED tube | B7: 3000 | C7: =750/B7 -> 0.25 | E7: 20 | F7: =(E7*8*60*60)/1000 -> 576 | G7: =(E7*Summary!B$4)/1000 -> 0.24 | H7: =I7*'Per Room Fit Out'!R$2 -> 51048 | I7: =G7*Summary!B$6 -> 72 | J7: =F7*'Per Room Fit Out'!G4 -> 54144 | K7: 0.04
F34: 0

Sheet Comps
A1: Type | B1: Amount | C1: Energy Use kw | D1: KWH | E1: KWH/Year | F1: KWH/Year Tot
A2: Laptop (half of population + office workers) | B2: =TRUNC('Per Room Fit Out'!R6)+(B3/2) -> 792 | C2: 0.05 | D2: =C2*Summary!B$5 -> 0.4 | E2: =D2*Summary!B$6 -> 120 | F2: =E2*B$2 -> 95040
A3: Monitor (2* office workers) | B3: =('Per Room Fit Out'!R4-B4)*2 -> 592 | C3: 0.0125 | D3: =C3*Summary!B$5 -> 0.1 | E3: =D3*Summary!B$6 -> 30 | F3: =E3*B$2 -> 23760
A4: Desktop (Computer Cluster Only) | B4: =31+ 20+20 -> 71 | C4: 0.2 | D4: =C4*Summary!B$5 -> 1.6 | E4: =D4*Summary!B$6 -> 480 | F4: =E4*B$4 -> 34080
A5: Bigscreen (Lecture Theater + Meeting rooms) | B5: ='Per Room Fit Out'!R5 -> 21 | C5: 0.21 | D5: =C5*Summary!B$5 -> 1.68 | E5: =D5*Summary!B$6 -> 504 | F5: =E5*B$5 -> 10584
A6: Printers (1 in Every Office Space + 2*Library) | B6: ='Per Room Fit Out'!R9 -> 31 | C6: 0.11 | D6: =C6*Summary!B$5 -> 0.88 | E6: =D6*Summary!B$6 -> 264 | F6: =E6*B$5 -> 5544
F8: =SUM(F2:F5) -> 163464
C11: =B3*2 -> 1184

Sheet Other
A1: Type | B1: Amount of lifts | C1: Max KWH/day | D1: Max KWH/year | E1: Lifts KWH year
A2: Lift | B2: 3 | C2: 5 | D2: =C2*365 -> 1825 | E2: =D2*B2 -> 5475
B3: KW | C3: h | D3: KWH/day | E3: KWH/Year | F3: Amount | G3: Final KWH/Year
A4: Pump | B4: 3.4 | C4: 14 | D4: =B4*C4 -> 47.6 | E4: =D4*Summary!B$6 -> 14280
A5: EV Chargers | B5: 7 | C5: 6 | D5: =B5*C5 -> 42 | E5: =D5*Summary!B$6 -> 12600 | F5: 15 | G5: =E5*F5 -> 189000
J6: Cost to offset | K6: 95 | L6: per tonne
B7: KW | C7: Time Till Full charge | D7: CO2 Emissions KG | E7: CO2 Emissions Tonne | F7: Cost/hour in offsetting | G7: Cost/hour in power | H7: Cost/hour | J7: Cost of electricity | K7: 77.89 | L7: per mwh | M7: =K7/1000 -> 0.07789 | N7: per kwh
A8: EV COST | B8: 7 | C8: =60/B8 -> 8.5714286 | D8: =B8*0.233 -> 1.631 | E8: =D8/1000 -> 0.001631 | F8: =E8*K$6 -> 0.154945 | G8: =B8*M$7 -> 0.54523 | H8: =F8+G8 -> 0.700175
B9: 3.7 | C9: =60/B9 -> 16.216216 | D9: =B9*0.233 -> 0.8621 | E9: =D9/1000 -> 0.0008621 | F9: =E9*K$6 -> 0.0818995 | G9: =B9*M$7 -> 0.288193 | H9: =F9+G9 -> 0.3700925
B10: 22 | C10: =60/B10 -> 2.7272727 | D10: =B10*0.233 -> 5.126 | E10: =D10/1000 -> 0.005126 | F10: =E10*K$6 -> 0.48697 | G10: =B10*M$7 -> 1.71358 | H10: =F10+G10 -> 2.20055
B11: 43 | C11: =60/B11 -> 1.3953488 | D11: =B11*0.233 -> 10.019 | E11: =D11/1000 -> 0.010019 | F11: =E11*K$6 -> 0.951805 | G11: =B11*M$7 -> 3.34927 | H11: =F11+G11 -> 4.301075
B12: 50 | C12: =60/B12 -> 1.2 | D12: =B12*0.233 -> 11.65 | E12: =D12/1000 -> 0.01165 | F12: =E12*K$6 -> 1.10675 | G12: =B12*M$7 -> 3.8945 | H12: =F12+G12 -> 5.00125
B13: 150 | C13: =60/B13 -> 0.4 | D13: =B13*0.233 -> 34.95 | E13: =D13/1000 -> 0.03495 | F13: =E13*K$6 -> 3.32025 | G13: =B13*M$7 -> 11.6835 | H13: =F13+G13 -> 15.00375

Sheet Solar
A1: Type | B1: Area | C1: kwp | D1: KPW produced | E1: cost m2 | F1: Items required | G1: cost | H1: area
A2: ECO WORTHY | B2: =1.335*0.67*6 -> 5.3667 | C2: 1.17 | D2: =C2*960 -> 1123.2 | E2: 1769 | F2: =OVERENERGy!D7/D2 -> 934.17023 | G2: =F2*E2*H2 -> 8.2848986e+09 | H2: =B2*F2 -> 5013.4114
A6: 1kwp | B6: 6m2 | D6: 790 kwh | K6: 146 kwh/m2.day
A7: 250 units at 60kg each

Sheet OVERENERGy
A1: Floor | B1: KWH per m2 day | C1: m2 | D1: kwh/year | E1: units needed | F1: MWH/year | I1: Floor | J1: KWH per m2 day | K1: m2 | L1: kwh/year | M1: units needed | N1: MWH/year | P1: Floor | Q1: KWH per m2 day | R1: m2 | S1: kwh/year | T1: units needed | U1: MWH/year
A2: Gronud | B2: 92 | C2: 2944 | D2: =B2*C2 -> 270848 | E2: =D2/874.5 -> 309.71755 | F2: =D2/1000 -> 270.848 | I2: Gronud | J2: 539 | K2: 2944 | L2: =J2*K2 -> 1586816 | M2: =L2/874.5 -> 1814.5409 | N2: =L2/1000 -> 1586.816 | P2: Gronud | Q2: 50 | R2: 2944 | S2: =Q2*R2 -> 147200 | T2: =S2/874.5 -> 168.32476 | U2: =S2/1000 -> 147.2
A3: 1 | B3: 92 | C3: 2944 | D3: =B3*C3 -> 270848 | E3: =D3/874.5 -> 309.71755 | F3: =D3/1000 -> 270.848 | I3: 1 | J3: 539 | K3: 2944 | L3: =J3*K3 -> 1586816 | M3: =L3/874.5 -> 1814.5409 | N3: =L3/1000 -> 1586.816 | P3: 1 | Q3: 50 | R3: 2944 | S3: =Q3*R3 -> 147200 | T3: =S3/874.5 -> 168.32476 | U3: =S3/1000 -> 147.2
A4: 2 | B4: 92 | C4: 2160 | D4: =B4*C4 -> 198720 | E4: =D4/874.5 -> 227.23842 | F4: =D4/1000 -> 198.72 | I4: 2 | J4: 539 | K4: 2160 | L4: =J4*K4 -> 1164240 | M4: =L4/874.5 -> 1331.3208 | N4: =L4/1000 -> 1164.24 | P4: 2 | Q4: 50 | R4: 2160 | S4: =Q4*R4 -> 108000 | T4: =S4/874.5 -> 123.49914 | U4: =S4/1000 -> 108
A5: 3 | B5: 92 | C5: 2153 | D5: =B5*C5 -> 198076 | E5: =D5/874.5 -> 226.502 | F5: =D5/1000 -> 198.076 | I5: 3 | J5: 539 | K5: 2153 | L5: =J5*K5 -> 1160467 | M5: =L5/874.5 -> 1327.0063 | N5: =L5/1000 -> 1160.467 | P5: 3 | Q5: 50 | R5: 2153 | S5: =Q5*R5 -> 107650 | T5: =S5/874.5 -> 123.09891 | U5: =S5/1000 -> 107.65
A6: 4 | B6: 92 | C6: 1204 | D6: =B6*C6 -> 110768 | E6: =D6/874.5 -> 126.66438 | F6: =D6/1000 -> 110.768 | I6: 4 | J6: 539 | K6: 1204 | L6: =J6*K6 -> 648956 | M6: =L6/874.5 -> 742.08805 | N6: =L6/1000 -> 648.956 | P6: 4 | Q6: 50 | R6: 1204 | S6: =Q6*R6 -> 60200 | T6: =S6/874.5 -> 68.839337 | U6: =S6/1000 -> 60.2
C7: =SUM(C2:C6) -> 11405 | D7: =SUM(D2:D6) -> 1049260 | E7: =D7/874.5 -> 1199.8399 | F7: =D7/1000 -> 1049.26 | K7: =SUM(K2:K6) -> 11405 | L7: =SUM(L2:L6) -> 6147295 | M7: =L7/874.5 -> 7029.4969 | N7: =L7/1000 -> 6147.295 | R7: =SUM(R2:R6) -> 11405 | S7: =SUM(S2:S6) -> 570250 | T7: =S7/874.5 -> 652.08691 | U7: =S7/1000 -> 570.25
I9: Floor | J9: KWH per m2 day | K9: m2 | L9: kwh/year | M9: units needed | N9: MWH/year
A10: Roof area | F10: KG | G10: Power | H10: Orientation | I10: Gronud | J10: 20 | K10: 2944 | L10: =J10*K10 -> 58880 | M10: =L10/874.5 -> 67.329903 | N10: =L10/1000 -> 58.88
A11: 1 | B11: 323.76168 | C11: =B11/6 -> 53.960281 | D11: =C11 -> 53.960281 | E11: =TRUNC(D11) -> 53 | F11: =E11*60 -> 3180 | G11: =E11*425.275 -> 22539.575 | H11: -9 | I11: 1 | J11: 20 | K11: 2944 | L11: =J11*K11 -> 58880 | M11: =L11/874.5 -> 67.329903 | N11: =L11/1000 -> 58.88
C12: =B12/6 -> 0 | D12: =C12 -> 0 | E12: =TRUNC(D12) -> 0 | I12: 2 | J12: 20 | K12: 2160 | L12: =J12*K12 -> 43200 | M12: =L12/874.5 -> 49.399657 | N12: =L12/1000 -> 43.2
A13: 3 | B13: 851.5472 | C13: =B13/6 -> 141.92453 | D13: =C13 -> 141.92453 | E13: =TRUNC(D13) -> 141 | F13: =E13*60 -> 8460 | G13: =E13*830.82 -> 117145.62 | H13: 128 | I13: 3 | J13: 20 | K13: 2153 | L13: =J13*K13 -> 43060 | M13: =L13/874.5 -> 49.239565 | N13: =L13/1000 -> 43.06
A14: 4 | B14: 934.06053 | C14: =B14/6 -> 155.67675 | D14: =C14 -> 155.67675 | E14: =TRUNC(D14) -> 155 | F14: =E14*60 -> 9300 | G14: =E14*909.272 -> 140937.16 | H14: 180 | I14: 4 | J14: 20 | K14: 1204 | L14: =J14*K14 -> 24080 | M14: =L14/874.5 -> 27.535735 | N14: =L14/1000 -> 24.08
C15: =SUM(C11:C14) -> 351.56157 | E15: =SUM(E11:E14) -> 349 | K15: =SUM(K10:K14) -> 11405 | L15: =SUM(L10:L14) -> 228100 | M15: =L15/874.5 -> 260.83476 | N15: =L15/1000 -> 228.1
A20: Roof area | B20: KG | C20: m2 | H20: =SUM(G11:G14) -> 280622.35 | L20: Roof Area | M20: Amount of Solar Pannels | N20: KWH/Year
A21: 1 | B21: =F11 -> 3180 | C21: =B21/10 -> 318 | L21: 1 | M21: =E11*3 -> 159 | N21: =E11*657.829 -> 34864.937
A22: 2 | B22: =F12 -> 0 | C22: =B22/10 -> 0 | L22: 2 | M22: =E12*3 -> 0 | N22: 0
A23: 3 | B23: =F13 -> 8460 | C23: =B23/10 -> 846 | L23: 3 | M23: =E13*3 -> 423 | N23: =E13*830.82 -> 117145.62
A24: 4 | B24: =F14 -> 9300 | C24: =B24/10 -> 930 | L24: 4 | M24: =E14*3 -> 465 | N24: =E14*909.272 -> 140937.16
C25: =SUM(C21:C24) -> 2094 | L25: TOT | M25: =E15*3 -> 1047 | N25: =SUM(N21:N24) -> 292947.72

Sheet Per Room Fit Out
A1: Ground Floor | C1: Recommended Sizing | D1: People | E1: total size | F1: Lumems | G1: Lights required | H1: Lux Levels | I1: Room Type | J1: Computers | K1: Printers | L1: Big Screens | M1: Heating | N1: Canteens | O1: Canteens trunc
A2: total area | D2: =D4+D16 -> 535 | E2: =E4+E16+E3 -> 2300.4 | F2: =SUM(F3,F4,F16) -> 497140 | G2: =G4+G16 -> 174 | H2: =H4+H16 -> 5650 | M2: =E2*R$8 -> 2300.4 | Q2: Lighting | R2: =G2+G29+G55+G84+G109+G124 -> 709 | T2: {=_xlfn.UNIQUE(I:I,)} -> Room Type | U2: Amount | V2: Area
A3: Atrium | D3: N/A | E3: 374 | G3: =TRUNC(F3/3000) -> 0 | I3: Living room | M3: =E3*R$8 -> 374 | Q3: Total Pop | R3: =D2+D29+D55+D84+D109+D106 -> 1359 | T3: 0
A4: ACEDEMIC/PUBLIC | D4: =SUM(D5:D6) -> 435 | E4: =SUM(E5:E15) -> 1062.7 | F4: =SUM(F5:F13) -> 253570 | G4: =SUM(G5:G15) -> 94 | H4: =SUM(H5:H15) -> 2600 | M4: =SUM(M5:M15) -> 1062.7 | Q4: Office Laptops | R4: =SUM(J:J) -> 367 | T4: Living room | U4: =COUNTIF(I:I,T4) -> 12 | V4: =SUMIF(I:I,T4,E:E) -> 1448 | W4: =IF(T4="Office",300,IF(T4="WareHouse",200,IF(T4="Bathroom",500,IF(T4="Stair",100,IF(T4="Living room",150))))) -> 150 | X4: =W4*V4 -> 217200 | Y4: =SUMIF(I:I,T4,G:G) -> 48
A5: Library | D5: 85 | E5: 254 | F5: =E5*H5 -> 76200 | G5: =IF(TRUNC(F5/3000)=0,1,TRUNC(F5/3000,0)) -> 25 | H5: =IF(I5="Office",300,IF(I5="WareHouse",200,IF(I5="Bathroom",500,IF(I5="Stair",100,IF(I5="Living room",150))))) -> 300 | I5: Office | J5: 20 | K5: 2 | L5: 1 | M5: =E5*R$8 -> 254 | N5: =D5/20 -> 4.25 | O5: =TRUNC(N5) -> 4 | Q5: Big Screens | R5: =SUM(L:L) -> 21 | T5: Office | U5: =COUNTIF(I:I,T5) -> 49 | V5: =SUMIF(I:I,T5,E:E) -> 4762 | W5: =IF(T5="Office",300,IF(T5="WareHouse",200,IF(T5="Bathroom",500,IF(T5="Stair",100,IF(T5="Living room",150))))) -> 300 | X5: =W5*V5 -> 1428600 | Y5: =SUMIF(I:I,T5,G:G) -> 454
A6: Lecture Theatre | D6: 350 | E6: 219 | F6: =E6*H6 -> 65700 | G6: =IF(TRUNC(F6/3000)=0,1,TRUNC(F6/3000,0)) -> 21 | H6: =IF(I6="Office",300,IF(I6="WareHouse",200,IF(I6="Bathroom",500,IF(I6="Stair",100,IF(I6="Living room",150))))) -> 300 | I6: Office | L6: 2 | M6: =E6*R$8 -> 219 | Q6: Population Using Laptop (Not office) | R6: =(R3-R4)/2 -> 496 | T6: Warehouse | U6: =COUNTIF(I:I,T6) -> 5 | V6: =SUMIF(I:I,T6,E:E) -> 537 | W6: =IF(T6="Office",300,IF(T6="WareHouse",200,IF(T6="Bathroom",500,IF(T6="Stair",100,IF(T6="Living room",150))))) -> 200 | X6: =W6*V6 -> 107400 | Y6: =SUMIF(I:I,T6,G:G) -> 34
A7: Bike Storage | D7: N/A | E7: 295 | F7: =E7*H7 -> 59000 | G7: =IF(TRUNC(F7/3000)=0,1,TRUNC(F7/3000,0)) -> 19 | H7: =IF(I7="Office",300,IF(I7="WareHouse",200,IF(I7="Bathroom",500,IF(I7="Stair",100,IF(I7="Living room",150))))) -> 200 | I7: Warehouse | M7: =E7*R$8 -> 295 | Q7: Canteens | R7: =SUM(O:O) -> 26 | T7: Bathroom | U7: =COUNTIF(I:I,T7) -> 9 | V7: =SUMIF(I:I,T7,E:E) -> 546 | W7: =IF(T7="Office",300,IF(T7="WareHouse",200,IF(T7="Bathroom",500,IF(T7="Stair",100,IF(T7="Living room",150))))) -> 500 | X7: =W7*V7 -> 273000 | Y7: =SUMIF(I:I,T7,G:G) -> 88
A8: Changing/Shower rooms | D8: N/A | E8: 0 | F8: =E8*H8 -> 0 | G8: =IF(TRUNC(F8/3000)=0,1,TRUNC(F8/3000,0)) -> 1 | H8: =IF(I8="Office",300,IF(I8="WareHouse",200,IF(I8="Bathroom",500,IF(I8="Stair",100,IF(I8="Living room",150))))) -> 500 | I8: Bathroom | M8: =E8*R$8 -> 0 | Q8: Heating energy per sq m | R8: 1 | T8: Stair | U8: =COUNTIF(I:I,T8) -> 36 | V8: =SUMIF(I:I,T8,E:E) -> 3795 | W8: =IF(T8="Office",300,IF(T8="WareHouse",200,IF(T8="Bathroom",500,IF(T8="Stair",100,IF(T8="Living room",150))))) -> 100 | X8: =W8*V8 -> 379500 | Y8: =SUMIF(I:I,T8,G:G) -> 137
A9: Toilet Block 2 | D9: N/A | E9: 92 | F9: =E9*H9 -> 46000 | G9: =IF(TRUNC(F9/3000)=0,1,TRUNC(F9/3000,0)) -> 15 | H9: =IF(I9="Office",300,IF(I9="WareHouse",200,IF(I9="Bathroom",500,IF(I9="Stair",100,IF(I9="Living room",150))))) -> 500 | I9: Bathroom | M9: =E9*R$8 -> 92 | Q9: Printers | R9: =SUM(K:K) -> 31 | V9: =SUM(V4:V8) -> 11088 | W9: =SUM(W4:W8) -> 1250 | X9: =SUM(X4:X8) -> 2405700 | Y9: =SUM(Y4:Y8) -> 761
A10: Stair well CC | D10: N/A | E10: 19.35 | F10: =E10*H10 -> 1935 | G10: =IF(TRUNC(F10/3000)=0,1,TRUNC(F10/3000,0)) -> 1 | H10: =IF(I10="Office",300,IF(I10="WareHouse",200,IF(I10="Bathroom",500,IF(I10="Stair",100,IF(I10="Living room",150))))) -> 100 | I10: Stair | M10: =E10*R$8 -> 19.35 | Q10: Total Heating | R10: =M2+M29+M55+M109+M84 -> 7767.3
A11: Stair well CC | D11: N/A | E11: 19.35 | F11: =E11*H11 -> 1935 | G11: =IF(TRUNC(F11/3000)=0,1,TRUNC(F11/3000,0)) -> 1 | H11: =IF(I11="Office",300,IF(I11="WareHouse",200,IF(I11="Bathroom",500,IF(I11="Stair",100,IF(I11="Living room",150))))) -> 100 | I11: Stair | M11: =E11*R$8 -> 19.35 | Q11: Heating0 | R11: 110925
A12: Stair well CC | D12: N/A | E12: 18 | F12: =E12*H12 -> 1800 | G12: =IF(TRUNC(F12/3000)=0,1,TRUNC(F12/3000,0)) -> 1 | H12: =IF(I12="Office",300,IF(I12="WareHouse",200,IF(I12="Bathroom",500,IF(I12="Stair",100,IF(I12="Living room",150))))) -> 100 | I12: Stair | M12: =E12*R$8 -> 18 | Q12: Cooling | R12: 10091
A13: lift shaft | D13: N/A | E13: 10 | F13: =E13*H13 -> 1000 | G13: =IF(TRUNC(F13/3000)=0,1,TRUNC(F13/3000,0)) -> 1 | H13: =IF(I13="Office",300,IF(I13="WareHouse",200,IF(I13="Bathroom",500,IF(I13="Stair",100,IF(I13="Living room",150))))) -> 100 | I13: Stair | M13: =E13*R$8 -> 10
A14: utilities | D14: N/A | E14: 106 | F14: =E14*H14 -> 21200 | G14: =IF(TRUNC(F14/3000)=0,1,TRUNC(F14/3000,0)) -> 7 | H14: =IF(I14="Office",300,IF(I14="WareHouse",200,IF(I14="Bathroom",500,IF(I14="Stair",100,IF(I14="Living room",150))))) -> 200 | I14: Warehouse | M14: =E14*R$8 -> 106
A15: Water tank | D15: N/A | E15: 30 | F15: =E15*H15 -> 6000 | G15: =IF(TRUNC(F15/3000)=0,1,TRUNC(F15/3000,0)) -> 2 | H15: =IF(I15="Office",300,IF(I15="WareHouse",200,IF(I15="Bathroom",500,IF(I15="Stair",100,IF(I15="Living room",150))))) -> 200 | I15: Warehouse | M15: =E15*R$8 -> 30
A16: COMMERCIAL | D16: =SUM(D17:D23) -> 100 | E16: =SUM(E17:E28) -> 863.7 | F16: =SUM(F17:F28) -> 243570 | G16: =SUM(G17:G28) -> 80 | H16: =SUM(H17:H28) -> 3050 | M16: =SUM(M17:M28) -> 863.7
A17: Office 1 | D17: 20 | E17: 116 | F17: =E17*H17 -> 34800 | G17: =IF(TRUNC(F17/3000)=0,1,TRUNC(F17/3000,0)) -> 11 | H17: =IF(I17="Office",300,IF(I17="WareHouse",200,IF(I17="Bathroom",500,IF(I17="Stair",100,IF(I17="Living room",150))))) -> 300 | I17: Office | J17: 20 | K17: 1 | M17: =E17*R$8 -> 116
A18: Office 2 | D18: 16 | E18: 111 | F18: =E18*H18 -> 33300 | G18: =IF(TRUNC(F18/3000)=0,1,TRUNC(F18/3000,0)) -> 11 | H18: =IF(I18="Office",300,IF(I18="WareHouse",200,IF(I18="Bathroom",500,IF(I18="Stair",100,IF(I18="Living room",150))))) -> 300 | I18: Office | J18: 18 | K18: 1 | M18: =E18*R$8 -> 111
A19: Office 3 | D19: 11 | E19: 65 | F19: =E19*H19 -> 19500 | G19: =IF(TRUNC(F19/3000)=0,1,TRUNC(F19/3000,0)) -> 6 | H19: =IF(I19="Office",300,IF(I19="WareHouse",200,IF(I19="Bathroom",500,IF(I19="Stair",100,IF(I19="Living room",150))))) -> 300 | I19: Office | J19: 10 | K19: 1 | M19: =E19*R$8 -> 65
A20: Office 4 | D20: 13 | E20: 81 | F20: =E20*H20 -> 24300 | G20: =IF(TRUNC(F20/3000)=0,1,TRUNC(F20/3000,0)) -> 8 | H20: =IF(I20="Office",300,IF(I20="WareHouse",200,IF(I20="Bathroom",500,IF(I20="Stair",100,IF(I20="Living room",150))))) -> 300 | I20: Office | J20: 13 | K20: 1 | M20: =E20*R$8 -> 81
A21: Office 5 | D21: 13 | E21: 80 | F21: =E21*H21 -> 24000 | G21: =IF(TRUNC(F21/3000)=0,1,TRUNC(F21/3000,0)) -> 8 | H21: =IF(I21="Office",300,IF(I21="WareHouse",200,IF(I21="Bathroom",500,IF(I21="Stair",100,IF(I21="Living room",150))))) -> 300 | I21: Office | J21: 13 | K21: 1 | M21: =E21*R$8 -> 80
A22: Office 6 | D22: 12 | E22: 72 | F22: =E22*H22 -> 21600 | G22: =IF(TRUNC(F22/3000)=0,1,TRUNC(F22/3000,0)) -> 7 | H22: =IF(I22="Office",300,IF(I22="WareHouse",200,IF(I22="Bathroom",500,IF(I22="Stair",100,IF(I22="Living room",150))))) -> 300 | I22: Office | J22: 12 | K22: 1 | M22: =E22*R$8 -> 72
A23: meeting room | D23: 15 | E23: 102 | F23: =E23*H23 -> 30600 | G23: =IF(TRUNC(F23/3000)=0,1,TRUNC(F23/3000,0)) -> 10 | H23: =IF(I23="Office",300,IF(I23="WareHouse",200,IF(I23="Bathroom",500,IF(I23="Stair",100,IF(I23="Living room",150))))) -> 300 | I23: Office | L23: 1 | M23: =E23*R$8 -> 102
A24: break room | D24: =SUM(D17:D22) -> 85 | E24: 124 | F24: =E24*H24 -> 18600 | G24: =IF(TRUNC(F24/3000)=0,1,TRUNC(F24/3000,0)) -> 6 | H24: =IF(I24="Office",300,IF(I24="WareHouse",200,IF(I24="Bathroom",500,IF(I24="Stair",100,IF(I24="Living room",150))))) -> 150 | I24: Living room | L24: 1 | M24: =E24*R$8 -> 124 | N24: =D24/20 -> 4.25 | O24: =TRUNC(N24) -> 4
A25: toilet block 1 | D25: N/A | E25: 64 | F25: =E25*H25 -> 32000 | G25: =IF(TRUNC(F25/3000)=0,1,TRUNC(F25/3000,0)) -> 10 | H25: =IF(I25="Office",300,IF(I25="WareHouse",200,IF(I25="Bathroom",500,IF(I25="Stair",100,IF(I25="Living room",150))))) -> 500 | I25: Bathroom | M25: =E25*R$8 -> 64
A26: lift shaft | D26: N/A | E26: 10 | F26: =E26*H26 -> 1000 | G26: =IF(TRUNC(F26/3000)=0,1,TRUNC(F26/3000,0)) -> 1 | H26: =IF(I26="Office",300,IF(I26="WareHouse",200,IF(I26="Bathroom",500,IF(I26="Stair",100,IF(I26="Living room",150))))) -> 100 | I26: Stair | M26: =E26*R$8 -> 10
A27: Stair well CC | D27: N/A | E27: 19.35 | F27: =E27*H27 -> 1935 | G27: =IF(TRUNC(F27/3000)=0,1,TRUNC(F27/3000,0)) -> 1 | H27: =IF(I27="Office",300,IF(I27="WareHouse",200,IF(I27="Bathroom",500,IF(I27="Stair",100,IF(I27="Living room",150))))) -> 100 | I27: Stair | M27: =E27*R$8 -> 19.35
A28: Stair well CC | D28: N/A | E28: 19.35 | F28: =E28*H28 -> 1935 | G28: =IF(TRUNC(F28/3000)=0,1,TRUNC(F28/3000,0)) -> 1 | H28: =IF(I28="Office",300,IF(I28="WareHouse",200,IF(I28="Bathroom",500,IF(I28="Stair",100,IF(I28="Living room",150))))) -> 100 | I28: Stair | M28: =E28*R$8 -> 19.35
A29: First Floor | D29: =D31+D42 -> 265 | E29: =E31+E42 -> 1870.75 | F29: =SUM(F31,F42) -> 550475 | G29: =G31+G42 -> 181 | H29: =H31+H42 -> 5450 | M29: =M31+M42 -> 1870.75
A30: Atrium | D30: N/A | E30: 374 | G30: =TRUNC(F30/3000) -> 0 | M30: =E30*R$8 -> 374
A31: ACEDEMIC/PUBLIC | D31: =SUM(D32:D36) -> 165 | E31: =SUM(E32:E41) -> 1007.05 | F31: =SUM(F32:F41) -> 306905 | G31: =SUM(G32:G41) -> 101 | H31: =SUM(H32:H41) -> 2400 | M31: =SUM(M32:M41) -> 1007.05
A32: Library | D32: 85 | E32: 254 | F32: =E32*H32 -> 76200 | G32: =IF(TRUNC(F32/3000)=0,1,TRUNC(F32/3000,0)) -> 25 | H32: =IF(I32="Office",300,IF(I32="WareHouse",200,IF(I32="Bathroom",500,IF(I32="Stair",100,IF(I32="Living room",150))))) -> 300 | I32: Office | K32: 2 | L32: 1 | M32: =E32*R$8 -> 254 | N32: =D32/20 -> 4.25 | O32: =TRUNC(N32) -> 4
A33: Lecture Theatre | D33: N/A | E33: 309 | F33: =E33*H33 -> 92700 | G33: =IF(TRUNC(F33/3000)=0,1,TRUNC(F33/3000,0)) -> 30 | H33: =IF(I33="Office",300,IF(I33="WareHouse",200,IF(I33="Bathroom",500,IF(I33="Stair",100,IF(I33="Living room",150))))) -> 300 | I33: Office | M33: =E33*R$8 -> 309
A34: Computer Cluster | D34: 31 | E34: 159 | F34: =E34*H34 -> 47700 | G34: =IF(TRUNC(F34/3000)=0,1,TRUNC(F34/3000,0)) -> 15 | H34: =IF(I34="Office",300,IF(I34="WareHouse",200,IF(I34="Bathroom",500,IF(I34="Stair",100,IF(I34="Living room",150))))) -> 300 | I34: Office | K34: 1 | L34: 1 | M34: =E34*R$8 -> 159
A35: Seminar Room | D35: 25 | E35: 64 | F35: =E35*H35 -> 19200 | G35: =IF(TRUNC(F35/3000)=0,1,TRUNC(F35/3000,0)) -> 6 | H35: =IF(I35="Office",300,IF(I35="WareHouse",200,IF(I35="Bathroom",500,IF(I35="Stair",100,IF(I35="Living room",150))))) -> 300 | I35: Office | L35: 1 | M35: =E35*R$8 -> 64
A36: Seminar Room | D36: 24 | E36: 61 | F36: =E36*H36 -> 18300 | G36: =IF(TRUNC(F36/3000)=0,1,TRUNC(F36/3000,0)) -> 6 | H36: =IF(I36="Office",300,IF(I36="WareHouse",200,IF(I36="Bathroom",500,IF(I36="Stair",100,IF(I36="Living room",150))))) -> 300 | I36: Office | L36: 1 | M36: =E36*R$8 -> 61
A37: Toilet Block | D37: N/A | E37: 92 | F37: =E37*H37 -> 46000 | G37: =IF(TRUNC(F37/3000)=0,1,TRUNC(F37/3000,0)) -> 15 | H37: =IF(I37="Office",300,IF(I37="WareHouse",200,IF(I37="Bathroom",500,IF(I37="Stair",100,IF(I37="Living room",150))))) -> 500 | I37: Bathroom | M37: =E37*R$8 -> 92
A38: Stair well CC | D38: N/A | E38: 19.35 | F38: =E38*H38 -> 1935 | G38: =IF(TRUNC(F38/3000)=0,1,TRUNC(F38/3000,0)) -> 1 | H38: =IF(I38="Office",300,IF(I38="WareHouse",200,IF(I38="Bathroom",500,IF(I38="Stair",100,IF(I38="Living room",150))))) -> 100 | I38: Stair | M38: =E38*R$8 -> 19.35
A39: Stair well CC | D39: N/A | E39: 19.35 | F39: =E39*H39 -> 1935 | G39: =IF(TRUNC(F39/3000)=0,1,TRUNC(F39/3000,0)) -> 1 | H39: =IF(I39="Office",300,IF(I39="WareHouse",200,IF(I39="Bathroom",500,IF(I39="Stair",100,IF(I39="Living room",150))))) -> 100 | I39: Stair | M39: =E39*R$8 -> 19.35
A40: Stair well CC | D40: N/A | E40: 19.35 | F40: =E40*H40 -> 1935 | G40: =IF(TRUNC(F40/3000)=0,1,TRUNC(F40/3000,0)) -> 1 | H40: =IF(I40="Office",300,IF(I40="WareHouse",200,IF(I40="Bathroom",500,IF(I40="Stair",100,IF(I40="Living room",150))))) -> 100 | I40: Stair | M40: =E40*R$8 -> 19.35
...

Sheet Solar Pannel Dimentions
B1: Roof Are | C1: Outside Dimention | D1: Solar pannel area | E1: degrees | F1: Inside area | G1: area | H1: average rad | I1: tang | J1: reduce tang | K1: reduce deg | L1: rad | M1: area | N1: act | O1: Angle from 180
A2: 1 | B2: 387 | D2: 258 | E2: 74 | F2: =PI()*(15^2)*(E2/360) -> 145.29866 | G2: =F2+B2 -> 532.29866 | H2: =SQRT(G2/((E2/360)*PI())) -> 28.710327 | I2: =H2-15 -> 13.710327 | J2: =I2-1 -> 12.710327 | K2: =E2-4 -> 70 | L2: =J2+15 -> 27.710327 | M2: =(L2^2)*(K2/360)*PI() -> 469.06034 | N2: =M2-F2 -> 323.76168 | O2: =O3-E3 -> -9 | P2: =O2-E2 -> -83
E3: 70 | O3: =O4-E4 -> 61 | P3: =O2 -> -9
A4: 3 | B4: 964 | D4: 720 | E4: =38+29 -> 67 | F4: =PI()*(15^2)*(E4/360) -> 131.55419 | G4: =F4+B4 -> 1095.5542 | H4: =SQRT(G4/((E4/360)*PI())) -> 43.286836 | I4: =H4-15 -> 28.286836 | J4: =I4-1 -> 27.286836 | K4: =E4-4 -> 63 | L4: =J4+15 -> 42.286836 | M4: =(L4^2)*(K4/360)*PI() -> 983.10139 | N4: =M4-F4 -> 851.5472 | O4: =O5-E5 -> 128 | P4: =O3 -> 61
A5: 4 | B5: 1066 | D5: 924 | E5: 52 | F5: =PI()*(15^2)*(E5/360) -> 102.10176 | G5: =F5+B5 -> 1168.1018 | H5: =SQRT(G5/((E5/360)*PI())) -> 50.735855 | I5: =H5-15 -> 35.735855 | J5: =I5-1 -> 34.735855 | K5: =E5-4 -> 48 | L5: =J5+15 -> 49.735855 | M5: =(L5^2)*(K5/360)*PI() -> 1036.1623 | N5: =M5-F5 -> 934.06053 | O5: 180 | P5: =O4 -> 128
B8: 15 | C8: =15+15 -> 30 | D8: =387+509+1078+1066 -> 3040 | I8: =2.49/52 -> 0.047884615 | J8: =1-I8 -> 0.95211538
B9: =PI()*(B8^2) -> 706.85835 | C9: =PI()*(C8^2) -> 2827.4334 | D9: =(C9-B9)*(3/4) -> 1590.4313
H11: =15*2*PI()*(2.49/360) -> 0.65188048 | I11: =15*2*PI()*(4.5/360) -> 1.1780972 | J11: =15*2*PI()*(10/360) -> 2.6179939 | K11: =15*2*PI()*(4/360) -> 1.0471976
C13: =SQRT(3/4) -> 0.8660254 | F13: pi() | G13: r^2
