Workbook

Sheet person
A1: Number of people | B1: 1341 | H1: Total water use per person | I1: =F6+F13+F9+F11+F7+B9+F12 -> 118.8 | J1: l/day | K1: greywater produced | L1: =F6+F7+F9 -> 52.8 | M1: l/day
A2: Toilet to people ratio | B2: 0.076388889 | H2: Total water use | I2: =I1*B1 -> 159310.8 | J2: l/day | K2: greywater produced | L2: =L1*B1 -> 70804.8 | M2: l/day
A3: number of toilets | B3: =B1/50 -> 26.82 | K3: greywater recycled | L3: =B9+B10+B11+B12 -> 49 | M3: l/day
A4: Greywater | E4: Bluewater | K4: Greywater recycled | L4: =(B9+B10+B12)*B1 -> 65709 | M4: l/day
A5: uses | B5: needs per person | E5: uses | F5: needs per person
A6: Toilet flushes | B6: 48.5 | C6: l/day | E6: basin | F6: 6.8 | G6: l/day
E7: sink | F7: 16 | G7: l/day | H7: make occupancy template
E8: Mixer showers | F8: =12*5 -> 60 | G8: l/day | H8: water tank on weekends
A9: Dual toilet flushes | B9: =30/2 -> 15 | C9: l/day | E9: Electric showers/low flow showerhead | F9: 30 | G9: l/day | H9: think about usage of different type of user
A10: Gardening | B10: 15 | C10: l/day | E10: washing machine | H10: promote behavioral change
A11: waterless urinals | B11: 0 | C11: l/day | E11: dishwasher | F11: 30 | G11: l/day | H11: list of wtaer saving devices
A12: Water fountain | B12: 19 | C12: l/day | E12: drinking water | F12: 3 | G12: l/day | H12: compare with other commercial buildings
E13: cleaning | F13: 18 | H13: state savings
H14: pump calculations and energy
B15: 109 | C15: l/day | D15: lost leakages | H15: mains water straight to devices
H16: how often tank needs to be emptied
H17: spit water usage up
H18: greywater filtration disinfection
H19: sizing of tank and pump
H20: number of cyclists and showers
H21: sheets with calcs on
H22: hgroundwater storage tank and pump
H23: rainwater and greywater treatment systems

Sheet Usage baseline and intervention
A1: Water saving devices | B1: Toilet flushing (l/day) | C1: Basins (l/day) | D1: Showers (l/day) | E1: Washing machines (l/day) | F1: kitchen sinks (l) | G1: dishwasher (l/day) | H1: drinking water (l/day) | I1: Totals (l/day) | J1: Savings (l/day)
A2: Baseline | B2: =9*3 -> 27 | C2: =(2*1.3)+(2.7) -> 5.3 | D2: =6*8 -> 48 | E2: 50 | F2: =8.3/2 -> 4.15 | G2: =14*2 -> 28 | H2: 3 | I2: =SUM(B2:H2) -> 165.45 | J2: 0
A3: Electric showers | B3: =9*3 -> 27 | C3: =(2*1.3)+(2.7) -> 5.3 | D3: =6*8 -> 48 | E3: 50 | F3: =8.3/2 -> 4.15 | G3: 28 | H3: 3 | I3: =SUM(B3:H3) -> 165.45 | J3: =$I$2-I3 -> 0
A4: Dual flush toilets | B4: =(6*1)+(4*2) -> 14 | C4: =(2*1.3)+(2.7) -> 5.3 | D4: =D2 -> 48 | E4: 50 | F4: =8.3/2 -> 4.15 | G4: 28 | H4: 3 | I4: =SUM(B4:H4) -> 152.45 | J4: =$I$2-I4 -> 13
A5: Sensor taps | B5: =9*3 -> 27 | C5: =(2*0.5)+(1) -> 2 | D5: =D4 -> 48 | E5: 50 | F5: =8.3/2 -> 4.15 | G5: 28 | H5: 3 | I5: =SUM(B5:H5) -> 162.15 | J5: =$I$2-I5 -> 3.3
A6: leak detection systems | B6: =9*3 -> 27 | C6: 5.3 | D6: =D4 -> 48 | E6: 50 | F6: =8.3/2 -> 4.15 | G6: 28 | H6: 3 | I6: =SUM(B6:H6) -> 165.45
A7: eco dishwasher | B7: =9*3 -> 27 | C7: 5.3 | D7: =D5 -> 48 | E7: 50 | F7: =8.3/2 -> 4.15 | G7: =10*2 -> 20 | H7: 3 | I7: =SUM(B7:H7) -> 157.45 | J7: =$I$2-I7 -> 8
A8: waterless urinals | B8: 0 | C8: 5.3 | D8: =D6 -> 48 | E8: 50 | F8: =8.3/2 -> 4.15 | G8: 28 | H8: 3 | I8: =SUM(B8:H8) -> 138.45 | J8: =$I$2-I8 -> 27
A9: Behavioural change | B9: =9*3 -> 27 | C9: 5.3 | D9: =6*5 -> 30 | E9: 50 | F9: =8.3/2 -> 4.15 | G9: 28 | H9: 3 | I9: =SUM(B9:H9) -> 147.45 | J9: =$I$2-I9 -> 18
A10: eco wash cycle | B10: =9*3 -> 27 | C10: 5.3 | D10: 48 | E10: 35 | F10: =8.3/2 -> 4.15 | G10: 28 | H10: 3 | I10: =SUM(B10:H10) -> 150.45 | J10: =$I$2-I10 -> 15
A11: Water Usage | B11: 14 | C11: 2 | D11: 30 | E11: 35 | F11: 4.15 | G11: 20 | H11: 3 | I11: =SUM(B11:H11) -> 108.15 | J11: =$I$2-I11 -> 57.3 | L11: 2000 | M11: people
H12: Total savings | I12: =J4+J5+J7+J9+J10 -> 57.3 | J12: l/day
L13: height 28m
A14: regular toilet | B14: 9 | C14: lpf
A15: dual flush | B15: 4 | C15: lpf
B16: 6 | C16: lpf
A18: Modern dishwasher | B18: 14 | C18: l/cycle
A19: Eco setting | B19: 10 | C19: l/cycle
A21: Traditional taps | B21: 4 | C21: l/min
A22: Sensor taps | B22: 1.5 | C22: l/min
A24: Mixer/power showers | B24: 12 | C24: l/min
A25: Electric Showers | B25: 6 | C25: l/min
A27: Behavioural change
A28: shower time | B28: 8 | C28: mins
B29: 5 | C29: mins
A30: Drinking water | B30: 3 | C30: l
A32: leakages | B32: 55 | C32: l

Sheet Types of users
A1: Male Researcher | B1: litres | C1: Female Researcher | D1: litres | E1: Male Student | F1: litres | G1: Female Student | H1: litres | I1: Cyclist who shower | J1: litres | K1: Male visitor | L1: litres | M1: Female visitor | N1: litres | O1: Male cafe worker | P1: litres | Q1: Female Café worker | R1: litres | S1: People using canteen | X1: Male nurse | Y1: litres | Z1: Female nurse | AB1: Café | AD1: Lab worker
A2: toilet | B2: 4 | C2: toilet | D2: 4 | E2: toilet | F2: 4 | G2: toilet | H2: 4 | I2: Shower | J2: 6 | K2: Toilet | L2: 4 | M2: Toilet | N2: 4 | O2: toilet | P2: 4 | Q2: toilet | R2: 4 | S2: Kitchen sink | T2: 8.3 | U2: lpm | X2: toilet | Y2: 4 | Z2: toilet | AA2: 4 | AB2: 28 | AC2: l/seat
A3: basin | B3: 0.5 | C3: basin | D3: 0.5 | E3: basin | F3: 0.5 | G3: basin | H3: 0.5 | I3: duration | J3: 8 | K3: Basin | L3: 0.5 | M3: Basin | N3: 0.5 | O3: basin | P3: 0.5 | Q3: basin | R3: 0.5 | S3: Washing hands/dishes | T3: =(T2/60)*V3 -> 2.7666667 | V3: 20 | W3: seconds | X3: basin | Y3: 0.5 | Z3: basin | AA3: 0.5
S4: Drinking/kettle/pot noodle | T4: =T3 -> 2.7666667 | V4: 20 | W4: seconds
A5: toilet | B5: 6 | C5: toilet | D5: 6 | E5: toilet | F5: 6 | G5: toilet | H5: 6 | O5: toilet | P5: 6 | Q5: toilet | R5: 6 | S5: Dishwasher | T5: 20 | U5: lpc | X5: toilet | Y5: 6 | Z5: toilet | AA5: 6
A6: basin | B6: 1 | C6: basin | D6: 1 | E6: basin | F6: 1 | G6: basin | H6: 1 | O6: basin | P6: 1 | Q6: basin | R6: 1 | T6: =20/4 -> 5 | X6: basin | Y6: 1 | Z6: basin | AA6: 1
X7: drinking water | Y7: 3 | Z7: drinking water | AA7: 3
A8: drinking water | B8: 3 | C8: drinking water | D8: 3 | E8: drinking water | F8: 3 | G8: drinking water | H8: 3 | K8: Drinking water | L8: 3 | M8: Drinking water | N8: 3 | O8: drinking water | P8: 3 | Q8: drinking water | R8: 3 | X8: sink | Y8: 0.75
O10: Dishwasher | P10: 20 | Q10: cleaning | R10: 18
A11: total (l/day) | B11: =((B2+B3)*2)+(B5+B6)+B8 -> 19 | C11: Total (l/day) | D11: =((D2+D3)*2)+(D5+D6)+D8 -> 19 | E11: Total (l/day) | F11: 19 | G11: Total (l/day) | H11: 19 | I11: Total (l/day) | J11: =J2*J3 -> 48 | K11: Total (l/day) | L11: =((L2+L3)*2)+L8 -> 12 | M11: Total (l/day) | N11: =((N2+N3)*2)+N8 -> 12 | O11: Total (l/day) | P11: =19+18 -> 37 | Q11: Total (l/day) | R11: =18+19 -> 37 | S11: Total (l/day) | T11: =T3+T4+T6 -> 10.533333 | X11: Total (l/day) | Y11: =((Y2+Y3)*2)+((Y5+Y6)*1)+Y7+(Y8*10) -> 26.5 | AA11: =((Y2+Y3)*2)+((Y5+Y6)*1)+Y7+(Y8*10) -> 26.5

Sheet Totals average weekday
B1: no of people | C1: Total water usage (l/day) | E1: Basins | F1: Greywater produced (l/day) | G1: l/hr | H1: l/min | I1: l/s | J1: Greywater for toilet flushing (l/day) | K1: (l/hr) | L1: l/min | M1: l/s
A2: male s | B2: 150 | C2: =B2*'Types of users'!F11 -> 2850 | E2: =(((0.5*2)+(1*1))) -> 2 | F2: =C16+C13+E3+C17+E4+E5+E6+E7+E8+E9+E13+E16+(18*B6)+(18*B7)+E10+E11 -> 10525 | G2: =F2/24 -> 438.54167 | H2: =G2/60 -> 7.3090278 | I2: =H2/60 -> 0.12181713 | J2: =SUM(J3:J4) -> 10180 | K2: =J2/24 -> 424.16667 | L2: =K2/60 -> 7.0694444 | M2: =L2/60 -> 0.11782407
A3: female s | B3: 150 | C3: =B3*'Types of users'!H11 -> 2850 | E3: =E2*B2 -> 300 | F3: pond? | I3: m3/s | J3: =((4*2)+(6*1))*(B2+B3+B10+B11+B8+B9) -> 9380 | M3: m3/s
A4: male v | B4: 50 | C4: =B4*'Types of users'!L11 -> 600 | E4: =E2*B3 -> 300 | F4: rainwater? | I4: =I2/1000 -> 0.00012181713 | J4: =(4*2)*(B4+B5) -> 800 | M4: =M2/1000 -> 0.00011782407
A5: female v | B5: 50 | C5: ='Types of users'!N11*B5 -> 600 | E5: =B6*E2 -> 20
A6: male cw | B6: 10 | C6: ='Types of users'!P11*B6 -> 370 | E6: =B7*E2 -> 20 | J6: =J2/1000 -> 10.18 | K6: m3/day
A7: female cw | B7: 10 | C7: =B7*'Types of users'!R11 -> 370 | E7: =B8*E2 -> 360
A8: male r | B8: 180 | C8: =B8*'Types of users'!B11 -> 3420 | E8: =B9*E2 -> 360 | H8: =(J2/C18)*100 -> 44.73742
A9: female r | B9: 180 | C9: =B9*'Types of users'!D11 -> 3420 | E9: =6*B17 -> 450 | H9: =(F2/C18)*100 -> 46.253571
A10: Nurse m | B10: 5 | C10: ='Types of users'!Y11*'Totals average weekday'!B10 -> 132.5 | E10: =((0.75*10)+(0.5*2)+(1*1))*5 -> 47.5 | F10: =SUM(E3:E16)-40 -> 2115
A11: nurse f | B11: 5 | C11: 132.5 | E11: =((0.75*10)+(0.5*2)+(1*1))*5 -> 47.5
A12: café | B12: 125 | C12: =B12*'Types of users'!AB3 -> 0
A13: showers | B13: 150 | C13: =B13*'Types of users'!J11 -> 7200 | E13: =2.5*B5 -> 125 | J13: =(F2/J2)*100 -> 103.389
A14: Female lab
A15: Male lab
A16: Dishwasher | C16: 20 | E16: 125
A17: canteen | B17: 75 | C17: =B17*'Types of users'!T11 -> 790 | E17: =E3+E4+E7+E8+E9+E10+E11+E13+E16 -> 2115
A18: total | C18: =SUM(C2:C17) -> 22755
B19: =SUM(B2:B17) -> 1140 | C19: =C18/1000 -> 22.755 | D19: m3/day

Sheet Generalised usage
A1: Area | B1: l/day | F1: Café | G1: savings (%) | J1: Average area | K1: 2132 | L1: m2
A2: Kitchen/café | B2: ='Types of users'!AB2*'Totals average weekday'!B12 -> 3500 | F2: leak detection systems | G2: 10 | J2: cleaning | K2: 15 | L2: l/10m2 | M2: Sm cleaning 2024
A3: café savings | B3: =F8 -> 2450 | K3: 25 | L3: l/10m2
A4: Toilet flushing | B4: =((((4*2)+(6*1))*('Totals average weekday'!B2+'Totals average weekday'!B3+'Totals average weekday'!B8+'Totals average weekday'!B9+'Totals average weekday'!B10+'Totals average weekday'!B11+28)))+((4*2)*('Totals average weekday'!B4+'Totals average weekday'!B5)) -> 10572 | F4: more efficient devices | G4: 30
A5: Basins | B5: ='Totals average weekday'!E17 -> 2115 | K5: =K2/10 -> 1.5 | L5: l/m2
A6: Drinking water | B6: =3*('Totals average weekday'!B2+'Totals average weekday'!B3+'Totals average weekday'!B4+'Totals average weekday'!B5+'Totals average weekday'!B8+'Totals average weekday'!B9+'Totals average weekday'!B10+'Totals average weekday'!B11) -> 2310 | F6: =B2*0.1 -> 350 | K6: 2.5 | L6: l/m2
A7: Showers | B7: =(5*6)*'Totals average weekday'!B13 -> 4500 | F7: =B2*0.3 -> 1050
A8: Washing machines | B8: =35*2 -> 70 | E8: Café usage | F8: =B2-(F7) -> 2450
A9: canteen | B9: ='Totals average weekday'!C17 -> 790
A10: Cleaning | B10: =K1*K5 -> 3198
A11: Total | B11: =SUM(B3:B10) -> 26005
A12: Greywater produced | B12: =B9+B7+B5+(20*2)+B8 -> 7515

Sheet Neat copy
A1: User | B1: No Of people | C1: Max capacity | D1: Large flush (x1) (l/day) | E1: Small flush (x2) (l/day) | F1: Total toilet flush | G1: Basin (l/day) | H1: Kitchen sink (l/day) | I1: Drinking water | J1: Shower | K1: Dishwasher | L1: Cleaning | M1: Totals | N1: Totals max | P1: Café | Q1: litres
A2: Male researcher | B2: 180 | C2: 180 | D2: 6 | E2: 0 | F2: =D2+E2 -> 6 | G2: =(1.5/2)*3 -> 2.25 | H2: 0 | I2: 3 | J2: 0 | K2: 0 | L2: 0 | M2: =(B2*SUM(E2:L2)) -> 2025 | P2: per seat | Q2: 27
A3: Female researcher | B3: 180 | C3: 180 | D3: 6 | E3: 8 | F3: =D3+E3 -> 14 | G3: =(1.5/2)*3 -> 2.25 | H3: 0 | I3: 3 | J3: 0 | K3: 0 | L3: 0 | M3: =B3*SUM(F3:L3) -> 3465 | P3: seats | Q3: 125
A4: Male student | B4: 150 | C4: 255 | D4: 6 | E4: 0 | F4: =D4+E4 -> 6 | G4: =(1.5/2)*3 -> 2.25 | H4: 0 | I4: 3 | J4: 0 | K4: 0 | L4: 0 | M4: =B4*SUM(E4:L4) -> 1687.5 | P4: Occupancy | Q4: 0.8
A5: Female student | B5: 150 | C5: 255 | D5: 6 | E5: 8 | F5: =D5+E5 -> 14 | G5: =(1.5/2)*3 -> 2.25 | H5: 0 | I5: 3 | J5: 0 | K5: 0 | L5: 0 | M5: =SUM(F5:L5)*B5 -> 2887.5 | P5: Savings | Q5: 0.3
A6: Male Visitor | B6: 50 | C6: 50 | D6: 0 | E6: 0 | F6: =D6+E6 -> 0 | G6: =(1.5/2)*2 -> 1.5 | H6: 0 | I6: 3 | J6: 0 | K6: 0 | L6: 0 | M6: =SUM(D6:L6)*C6 -> 225
A7: Female Visitor | B7: 50 | C7: 50 | D7: 0 | E7: 8 | F7: =D7+E7 -> 8 | G7: =(1.5/2)*2 -> 1.5 | H7: 0 | I7: 3 | J7: 0 | K7: 0 | L7: 0 | M7: =SUM(F7:L7)*B7 -> 625
A8: cyclists who shower | B8: 10 | C8: 150 | D8: 0 | E8: 0 | F8: =D8+E8 -> 0 | G8: 0 | H8: 0 | I8: 0 | J8: =6*5 -> 30 | K8: 0 | L8: 0 | M8: =SUM(D8:L8)*B8 -> 300
A9: Male lab worker | B9: 22 | C9: 28 | D9: 6 | E9: 0 | F9: =D9+E9 -> 6 | G9: =(1.5/2)*3 -> 2.25 | H9: =8.3*2 -> 16.6 | I9: 3 | J9: 0 | K9: 0 | L9: 0 | M9: =SUM(E9:L9)*B9 -> 612.7
A10: Female lab worker | B10: 22 | C10: 28 | D10: 6 | E10: 8 | F10: =D10+E10 -> 14 | G10: =(1.5/2)*3 -> 2.25 | H10: =8.3*2 -> 16.6 | I10: 3 | J10: 0 | K10: 0 | L10: 0 | M10: =SUM(F10:L10)*B10 -> 788.7
A11: Male nurse | B11: 5 | C11: 5 | D11: 6 | E11: 0 | F11: =D11+E11 -> 6 | G11: =(1.5/2)*3 -> 2.25 | H11: 8.3 | I11: 3 | J11: 0 | K11: 0 | L11: 0 | M11: =SUM(E11:L11)*B11 -> 97.75
A12: Female nurse | B12: 5 | C12: 5 | D12: 6 | E12: 8 | F12: =D12+E12 -> 14 | G12: =(1.5/2)*3 -> 2.25 | H12: 8.3 | I12: 3 | J12: 0 | K12: 0 | L12: 0 | M12: =SUM(F12:L12)*B12 -> 137.75
A13: Cleaner | B13: 5 | C13: 5 | D13: 6 | E13: 8 | F13: =D13+E13 -> 14 | G13: 2.25 | H13: 0 | I13: 3 | J13: 0 | K13: 0 | L13: ='Generalised usage'!K1*'Generalised usage'!K5 -> 3198 | M13: =L13+(SUM(F13:I13)*B13) -> 3294.25
A14: Café | B14: 125 | C14: 125 | M14: =B20 -> 1687.5
A15: Canteen | B15: 75 | C15: 75 | D15: 0 | E15: 0 | F15: =D15+E15 -> 0 | G15: 0 | H15: =8.3/2 -> 4.15 | I15: 3 | J15: 0 | K15: =10*(B15/2) -> 375 | L15: 0 | M15: =(SUM(D15:J15)*B15)+K15 -> 911.25
A16: Sum | B16: =SUM(B2:B15) -> 1029 | C16: =SUM(C2:C15) -> 1391 | D16: =SUM(D2:D13) -> 54 | E16: =SUM(E2:E13) -> 48 | G16: =SUM(G2:G13) -> 23.25 | H16: =SUM(H9:H15) -> 53.95 | I16: =SUM(I2:I15) -> 36 | J16: =30 -> 30 | K16: =SUM(K2:K15) -> 375 | L16: =SUM(L2:L15) -> 3198 | M16: =SUM(M2:M15) -> 18744.9
A19: Types of Usage | B19: Usage (l/day) | C19: Maximum usage | D19: Greywater | E19: =B30 -> 3558.55
A20: Café | B20: =(Q2*Q3*0.8)-(Q2*Q3*0.3) -> 1687.5 | C20: =(Q2*Q3)-(Q2*Q3*0.3) -> 2362.5 | D20: Blackwater | E20: =B21+B20 -> 9297.5
A21: Toilet flushing | B21: =(F2*B2)+(F3*B3)+(F4*B4)+(F5*B5)+(F6*B6)+(F7*B7)+(F9*B9)+(F10*B10)+(F11*B11)+(F12*B12)+(F13*B13) -> 7610 | C21: =(F2*C2)+(F3*C3)+(F4*C4)+(F5*C5)+(F6*C6)+(F7*C7)+(F9*C9)+(F10*C10)+(F11*C11)+(F12*C12)+(F13*C13) -> 9830 | D21: No reusable | E21: =B23+B28 -> 5655
A22: Taps | B22: =(G2*B2)+(G3*B3)+(G4*B4)+(G5*B5)+(G6*B6)+(G7*B7)+(G9*B9)+(G10*B10)+(G11*B11)+(G12*B12)+(G13*B13) -> 1767.75 | C22: =(G2*C2)+(G3*C3)+(G4*C4)+(G5*C5)+(G6*C6)+(G7*C7)+(G9*C9)+(G10*C10)+(G11*C11)+(G12*C12)+(G13*C13) -> 2267.25
A23: Drinking water | B23: =(I2*B2)+(I3*B3)+(I4*B4)+(I5*B5)+(I6*B6)+(I7*B7)+(I9*B9)+(I10*B10)+(I11*B11)+(I12*B12)+(I13*B13) -> 2457 | C23: =(I2*C2)+(I3*C3)+(I4*C4)+(I5*C5)+(I6*C6)+(I7*C7)+(I9*C9)+(I10*C10)+(I11*C11)+(I12*C12)+(I13*C13) -> 3123 | D23: Types of Usage | E23: Usage (l/day)
A24: Showers | B24: =M8 -> 300 | C24: 300 | D24: Toilet flushing | E24: =B21 -> 7610
A25: Kitchen sinks | B25: =(H9*B9)+(H10+B10)+(H11+B11)+(H12+B12)+(H15+B15) -> 509.55 | C25: =(H9*C9)+(H10+C10)+(H11+C11)+(H12+C12)+(H15+C15) -> 615.15 | D25: Cleaning | E25: 3198
A26: Washing machines | B26: =2*35 -> 70 | C26: 70 | D26: Greywater produced | E26: =B30 -> 3558.55
A27: canteen | B27: =M15 -> 911.25 | C27: =(SUM(D15:J15)*C15)+K15 -> 911.25
A28: Cleaning | B28: =L13 -> 3198 | C28: =B28 -> 3198 | E28: =B21+B28 -> 10808
A29: Total | B29: =SUM(B20:B28) -> 18511.05 | C29: =SUM(C20:C28) -> 22677.15 | E29: =B30/B21 -> 0.46761498
A30: Greywater produced | B30: =B22+B24+B26+B27+B25 -> 3558.55 | C30: =SUM(C22+C25+C24+C27+C26) -> 4163.65 | E30: =(B21+B28)/B29 -> 0.58386747
E31: =(B30)/(B21+B28) -> 0.32925148
A32: waterless | D32: Toilet flushing
A33: Types of Usage | B33: Usage (l/day) | D33: Types of Usage | E33: Usage (l/day) | G33: Types of Usage | H33: Usage (l/day) | I33: basin
A34: Café | B34: 1687.5 | D34: Café | E34: 1687.5 | G34: Café | H34: 1687.5
A35: Toilet flushing | B35: =((F3)*(B2+B3+B4+B5+B9+B10+B11+B12+B13))+((F7)*(B6+B7)) -> 10866 | D35: Toilet flushing | E35: =(27*(B2+B3+B4+B5+B9+B10+B11+B12+B13))+(18*(B6+B7)) -> 21213 | G35: Toilet flushing | H35: 7610 | M35: Types of uage | N35: Usage (l/day) | O35: waterless | P35: dual flush | Q35: Electric showers | R35: Behavioural change | S35: Sensor taps | T35: Eco washing | U35: eco dishwash | V35: All intervensions
A36: Taps | B36: 1767.75 | D36: Taps | E36: 1767.75 | G36: Taps | H36: =((6)*(B2+B3+B4+B5+B9+B10+B11+B12+B13))+((4)*(B6+B7)) -> 4714 | M36: Café | N36: =B20 -> 1687.5 | O36: =N36 -> 1687.5 | P36: =O36 -> 1687.5 | Q36: =P36 -> 1687.5 | R36: =Q36 -> 1687.5 | S36: =R36 -> 1687.5 | T36: =S36 -> 1687.5 | U36: =T36 -> 1687.5 | V36: =U36 -> 1687.5
A37: Drinking water | B37: 2457 | D37: Drinking water | E37: 2457 | G37: Drinking water | H37: 2457 | M37: Toilet flushing | N37: =E35 -> 21213 | O37: =B21 -> 7610 | P37: =B35 -> 10866 | Q37: =N37 -> 21213 | R37: =Q37 -> 21213 | S37: =R37 -> 21213 | T37: =Q37 -> 21213 | U37: =R37 -> 21213 | V37: =O37 -> 7610
A38: Showers | B38: 300 | D38: Showers | E38: 300 | G38: Showers | H38: 300 | M38: Taps | N38: =H36 -> 4714 | O38: =N38 -> 4714 | P38: =O38 -> 4714 | Q38: =P38 -> 4714 | R38: =Q38 -> 4714 | S38: =B22 -> 1767.75 | T38: =N38 -> 4714 | U38: =O38 -> 4714 | V38: =S38 -> 1767.75
A39: Kitchen sinks | B39: 509.55 | D39: Kitchen sinks | E39: 509.55 | G39: Kitchen sinks | H39: 509.55 | M39: Drinking water | N39: =H37 -> 2457 | O39: =N39 -> 2457 | P39: =O39 -> 2457 | Q39: =P39 -> 2457 | R39: =Q39 -> 2457 | S39: =R39 -> 2457 | T39: =S39 -> 2457 | U39: =T39 -> 2457 | V39: =U39 -> 2457
A40: Washing machines | B40: 70 | D40: Washing machines | E40: 70 | G40: Washing machines | H40: 70 | M40: Showers | N40: =B67 -> 600 | O40: =N40 -> 600 | P40: =O40 -> 600 | Q40: =6*8*10 -> 480 | R40: =B24 -> 300 | S40: =600 -> 600 | T40: =R40 -> 300 | U40: =S40 -> 600 | V40: =R40 -> 300
A41: canteen | B41: 911.25 | D41: canteen | E41: 911.25 | G41: canteen | H41: 911.25 | M41: Kitchen sinks | N41: =B39 -> 509.55 | O41: =N41 -> 509.55 | P41: =O41 -> 509.55 | Q41: =P41 -> 509.55 | R41: =Q41 -> 509.55 | S41: =R41 -> 509.55 | T41: =S41 -> 509.55 | U41: =T41 -> 509.55 | V41: =Q41 -> 509.55
A42: Cleaning | B42: 3198 | D42: Cleaning | E42: 3198 | G42: Cleaning | H42: 3198 | M42: Washing machines | N42: =B54 -> 100 | O42: =N42 -> 100 | P42: =O42 -> 100 | Q42: =P42 -> 100 | R42: =Q42 -> 100 | S42: =R42 -> 100 | T42: 70 | U42: 100 | V42: =T42 -> 70
...

Sheet Sheet1
F1: User | G1: No Of people | H1: Large flush (x1) (l/day) | I1: Small flush (x2) (l/day) | J1: Total toilet flush | K1: Basin (l/day) | L1: Kitchen sink (l/day) | M1: Drinking water | N1: Shower | O1: Dishwasher | P1: Cleaning
A2: Male Researcher/Student | F2: Male researcher | G2: 180 | H2: 6 | I2: 0 | J2: =H2+I2 -> 6 | K2: =(1.5/2)*3 -> 2.25 | L2: 0 | M2: 3 | N2: 0 | O2: 0 | P2: 0
A3: Female Reseacher/Student | F3: Female researcher | G3: 180 | H3: 6 | I3: 8 | J3: =H3+I3 -> 14 | K3: =(1.5/2)*3 -> 2.25 | L3: 0 | M3: 3 | N3: 0 | O3: 0 | P3: 0
A4: Male Visitor | F4: Male student | G4: 150 | H4: 6 | I4: 0 | J4: =H4+I4 -> 6 | K4: =(1.5/2)*3 -> 2.25 | L4: 0 | M4: 3 | N4: 0 | O4: 0 | P4: 0
A5: Female Visitor | F5: Female student | G5: 150 | H5: 6 | I5: 8 | J5: =H5+I5 -> 14 | K5: =(1.5/2)*3 -> 2.25 | L5: 0 | M5: 3 | N5: 0 | O5: 0 | P5: 0
A6: Canteen | F6: Male Visitor | G6: 50 | H6: 0 | I6: 0 | J6: =H6+I6 -> 0 | K6: =(1.5/2)*2 -> 1.5 | L6: 0 | M6: 3 | N6: 0 | O6: 0 | P6: 0
F7: Female Visitor | G7: 50 | H7: 0 | I7: 8 | J7: =H7+I7 -> 8 | K7: =(1.5/2)*2 -> 1.5 | L7: 0 | M7: 3 | N7: 0 | O7: 0 | P7: 0
F8: cyclists who shower | G8: 10 | H8: 0 | I8: 0 | J8: =H8+I8 -> 0 | K8: 0 | L8: 0 | M8: 0 | N8: =6*5 -> 30 | O8: 0 | P8: 0
F9: Male lab worker | G9: 22 | H9: 6 | I9: 0 | J9: =H9+I9 -> 6 | K9: =(1.5/2)*3 -> 2.25 | L9: =8.3*2 -> 16.6 | M9: 3 | N9: 0 | O9: 0 | P9: 0
F10: Female lab worker | G10: 22 | H10: 6 | I10: 8 | J10: =H10+I10 -> 14 | K10: =(1.5/2)*3 -> 2.25 | L10: =8.3*2 -> 16.6 | M10: 3 | N10: 0 | O10: 0 | P10: 0
F11: Male nurse | G11: 5 | H11: 6 | I11: 0 | J11: =H11+I11 -> 6 | K11: =(1.5/2)*3 -> 2.25 | L11: 8.3 | M11: 3 | N11: 0 | O11: 0 | P11: 0
F12: Female nurse | G12: 5 | H12: 6 | I12: 8 | J12: =H12+I12 -> 14 | K12: =(1.5/2)*3 -> 2.25 | L12: 8.3 | M12: 3 | N12: 0 | O12: 0 | P12: 0
F13: Cleaner | G13: 5 | H13: 6 | I13: 8 | J13: =H13+I13 -> 14 | K13: 2.25 | L13: 0 | M13: 3 | N13: 0 | O13: 0 | P13: ='Generalised usage'!P1*'Generalised usage'!P5 -> 0
F14: Café | G14: 125
F15: Canteen | G15: 75 | H15: 0 | I15: 0 | J15: =H15+I15 -> 0 | K15: 0 | L15: =8.3/2 -> 4.15 | M15: 3 | N15: 0 | O15: =10*(G15/2) -> 375 | P15: 0

Sheet occupancy template
A1: {=+C1+A1:C21+A+A1:C22} -> 0 | B1: Percentage
A2: 1 | B2: 0 | C2: 0
A3: 2 | B3: 0 | C3: 0
A4: 3 | B4: 0 | C4: 0
A5: 4 | B5: 0 | C5: 0
A6: 5 | B6: 0 | C6: 0
A7: 6 | B7: 5 | C7: =B7 -> 5
A8: 7 | B8: 10 | C8: =B8 -> 10
A9: 8 | B9: 50 | C9: =B9 -> 50
A10: 9 | B10: 70 | C10: =B10 -> 70
A11: 10 | B11: 80 | C11: 95
A12: 11 | B12: 80 | C12: 95
A13: 12 | B13: 80 | C13: 95
A14: 13 | B14: 80 | C14: 95
A15: 14 | B15: 80 | C15: 95
A16: 15 | B16: 80 | C16: 95
A17: 16 | B17: 80 | C17: 95
A18: 17 | B18: 80 | C18: 95
A19: 18 | B19: 60 | C19: =B19 -> 60
A20: 19 | B20: 10 | C20: =B20 -> 10
A21: 20 | B21: 5 | C21: =B21 -> 5
A22: 21 | B22: 0 | C22: =B22 -> 0
A23: 22 | B23: 0 | C23: =B23 -> 0
A24: 23 | B24: 0 | C24: =B24 -> 0
A25: 24 | B25: 0 | C25: =B25 -> 0

Sheet Graphs
B1: Intervensions | C1: Baseline | D1: Intervension | E1: Percentage of savings from baseline
A2: Toilet flushing | C2: ='Neat copy'!E35 -> 21213 | D2: ='Neat copy'!B21 -> 7610 | E2: =100-((D2/C2)*100) -> 64.125772
A3: Taps | C3: ='Neat copy'!H36 -> 4714 | D3: ='Neat copy'!B22 -> 1767.75 | E3: =100-((D3/C3)*100) -> 62.5
A4: Washing Machines | C4: ='Neat copy'!B54 -> 100 | D4: ='Neat copy'!B40 -> 70 | E4: =100-((D4/C4)*100) -> 30
A5: Canteen | C5: ='Neat copy'!N43 -> 1061.25 | D5: ='Neat copy'!H41 -> 911.25 | E5: =100-((D5/C5)*100) -> 14.134276
A6: Showers | C6: ='Neat copy'!B67 -> 600 | D6: ='Neat copy'!B24 -> 300 | E6: =100-((D6/C6)*100) -> 50
A7: Café | C7: =D7+(D7*0.3) -> 2193.75 | D7: ='Neat copy'!B20 -> 1687.5 | E7: =100-((D7/C7)*100) -> 23.076923
A8: Total | C8: ='Neat copy'!N45 -> 35540.3 | D8: ='Neat copy'!B29 -> 18511.05 | E8: =100-((D8/C8)*100) -> 47.915324

Sheet Daily toilet habits
A1: Time (hr) | B1: Water usage (l/hr) | C1: Toilet flushing demand (l/hr) | D1: Greywater in tank
A2: 1 | B2: =C2 -> 0 | C2: 0 | D2: =D25+846 -> 4230
A3: 1.0416667 | B3: =C3 -> 0 | C3: 0 | D3: =D2+846 -> 5076
A4: 1.0833333 | B4: =C4 -> 0 | C4: 0 | D4: =D3+846 -> 5922
A5: 1.125 | B5: =C5 -> 0 | C5: 0 | D5: =D4+846 -> 6768
A6: 1.1666667 | B6: =C6 -> 0 | C6: 0 | D6: =D5+842 -> 7610
A7: 1.2083333 | B7: ='Neat copy'!$B$29*0.02 -> 370.221 | C7: ='Neat copy'!$B$21*0.02 -> 152.2 | D7: 7610 | E7: =1 -> 1
A8: 1.25 | B8: ='Neat copy'!$B$29*0.04 -> 740.442 | C8: ='Neat copy'!$B$21*0.04 -> 304.4 | D8: =D7-C7 -> 7457.8 | E8: =E7+1 -> 2
A9: 1.2916667 | B9: ='Neat copy'!$B$29*0.06 -> 1110.663 | C9: ='Neat copy'!$B$21*0.06 -> 456.6 | D9: =D8-C8 -> 7153.4 | E9: =E8+1 -> 3
A10: 1.3333333 | B10: ='Neat copy'!$B$29*0.09 -> 1665.9945 | C10: ='Neat copy'!$B$21*0.09 -> 684.9 | D10: =D9-C9 -> 6696.8 | E10: =E9+1 -> 4
A11: 1.375 | B11: ='Neat copy'!$B$29*0.12 -> 2221.326 | C11: ='Neat copy'!$B$21*0.12 -> 913.2 | D11: =D10-C10 -> 6011.9 | E11: =E10+1 -> 5
A12: 1.4166667 | B12: ='Neat copy'!$B$29*0.07 -> 1295.7735 | C12: ='Neat copy'!$B$21*0.07 -> 532.7 | D12: =D11-C11 -> 5098.7 | E12: =E11+1 -> 6
A13: 1.4583333 | B13: ='Neat copy'!$B$29*0.1 -> 1851.105 | C13: ='Neat copy'!$B$21*0.1 -> 761 | D13: =D12-C12 -> 4566 | E13: =E12+1 -> 7
A14: 1.5 | B14: ='Neat copy'!$B$29*0.13 -> 2406.4365 | C14: ='Neat copy'!$B$21*0.13 -> 989.3 | D14: =D13-C13 -> 3805 | E14: =E13+1 -> 8
A15: 1.5416667 | B15: ='Neat copy'!$B$29*0.1 -> 1851.105 | C15: ='Neat copy'!$B$21*0.1 -> 761 | D15: =D14-C14 -> 2815.7 | E15: =E14+1 -> 9
A16: 1.5833333 | B16: ='Neat copy'!$B$29*0.06 -> 1110.663 | C16: ='Neat copy'!$B$21*0.06 -> 456.6 | D16: =D15-C15 -> 2054.7 | E16: =E15+1 -> 10
A17: 1.625 | B17: ='Neat copy'!$B$29*0.07 -> 1295.7735 | C17: ='Neat copy'!$B$21*0.07 -> 532.7 | D17: =D16-C16 -> 1598.1 | E17: =E16+1 -> 11
A18: 1.6666667 | B18: ='Neat copy'!$B$29*0.08 -> 1480.884 | C18: ='Neat copy'!$B$21*0.08 -> 608.8 | D18: =D17-C17 -> 1065.4 | E18: =E17+1 -> 12
A19: 1.7083333 | B19: ='Neat copy'!$B$29*0.04 -> 740.442 | C19: ='Neat copy'!$B$21*0.04 -> 304.4 | D19: =D18-C18 -> 456.6 | E19: =E18+1 -> 13
A20: 1.75 | B20: ='Neat copy'!$B$29*0.02 -> 370.221 | C20: ='Neat copy'!$B$21*0.02 -> 152.2 | D20: =D19-C19 -> 152.2 | E20: =E19+1 -> 14
A21: 1.7916667 | B21: =0 -> 0 | C21: 0 | D21: 0 | E21: =E20+1 -> 15
A22: 1.8333333 | B22: =0 -> 0 | C22: 0 | D22: 846 | E22: =E21+1 -> 16
A23: 1.875 | B23: =0 -> 0 | C23: 0 | D23: =D22+846 -> 1692 | E23: =E22+1 -> 17
A24: 1.9166667 | B24: =0 -> 0 | C24: 0 | D24: =D23+846 -> 2538 | E24: =E23+1 -> 18
A25: 1.9583333 | B25: =0 -> 0 | C25: 0 | D25: =D24+846 -> 3384 | E25: =E24+1 -> 19
D32: =SUM(C7:C20) -> 7610

Sheet Weekday tank
B1: Intermittent supply of treated, reused greywater (different sources?) | C1: top up from mains to balance deficit for toilet flushing | F1: Water demand for toilet flushing
A2: Hour | B2: Treated Greywater flow into Tank (QRGW) (L/h) | C2: Potable water flow into Tank (QD) (L/h) | D2: Total Flow Into Tank that hour (Qin) (L/h) | E2: Cumulative flow in (L) | F2: Flow OUT of Tank that hour (Qout) (L/h) | G2: Cumulative flow out (L) | H2: Net Flow INTO tank that hour (Qin - Qout) (L/h) | I2: Cumulative NET Flow Into Tank (L/h) | J2: Level in the tank (L)
A3: 1 | B3: 846 | C3: 0 | D3: =B3+C3 -> 846 | E3: =D3 -> 846 | F3: 0 | G3: =F3 -> 0 | H3: =D3-F3 -> 846 | I3: =H3 -> 846
A4: =A3+1 -> 2 | B4: 846 | C4: 0 | D4: =B4+C4 -> 846 | E4: =E3+D4 -> 1692 | F4: 0 | G4: =G3+F4 -> 0 | H4: =D4-F4 -> 846 | I4: =I3+H4 -> 1692
A5: =A4+1 -> 3 | B5: 846 | C5: 0 | D5: =B5+C5 -> 846 | E5: =E4+D5 -> 2538 | F5: 0 | G5: =G4+F5 -> 0 | H5: =D5-F5 -> 846 | I5: =I4+H5 -> 2538
A6: =A5+1 -> 4 | B6: 846 | C6: 0 | D6: =B6+C6 -> 846 | E6: =E5+D6 -> 3384 | F6: 0 | G6: =G5+F6 -> 0 | H6: =D6-F6 -> 846 | I6: =I5+H6 -> 3384
A7: =A6+1 -> 5 | B7: 846 | C7: 0 | D7: =B7+C7 -> 846 | E7: =E6+D7 -> 4230 | F7: 0 | G7: =G6+F7 -> 0 | H7: =D7-F7 -> 846 | I7: =I6+H7 -> 4230
A8: =A7+1 -> 6 | B8: 0 | C8: 0 | D8: =B8+C8 -> 0 | E8: =E7+D8 -> 4230 | F8: ='Daily toilet habits'!C7 -> 152.2 | G8: =G7+F8 -> 152.2 | H8: =D8-F8 -> -152.2 | I8: =I7+H8 -> 4077.8
A9: =A8+1 -> 7 | B9: 0 | C9: 0 | D9: =B9+C9 -> 0 | E9: =E8+D9 -> 4230 | F9: ='Daily toilet habits'!C8 -> 304.4 | G9: =G8+F9 -> 456.6 | H9: =D9-F9 -> -304.4 | I9: =I8+H9 -> 3773.4
A10: =A9+1 -> 8 | B10: 0 | C10: 0 | D10: =B10+C10 -> 0 | E10: =E9+D10 -> 4230 | F10: ='Daily toilet habits'!C9 -> 456.6 | G10: =G9+F10 -> 913.2 | H10: =D10-F10 -> -456.6 | I10: =I9+H10 -> 3316.8
A11: =A10+1 -> 9 | B11: 0 | C11: 0 | D11: =B11+C11 -> 0 | E11: =E10+D11 -> 4230 | F11: ='Daily toilet habits'!C10 -> 684.9 | G11: =G10+F11 -> 1598.1 | H11: =D11-F11 -> -684.9 | I11: =I10+H11 -> 2631.9
A12: =A11+1 -> 10 | B12: 0 | C12: 0 | D12: =B12+C12 -> 0 | E12: =E11+D12 -> 4230 | F12: ='Daily toilet habits'!C11 -> 913.2 | G12: =G11+F12 -> 2511.3 | H12: =D12-F12 -> -913.2 | I12: =I11+H12 -> 1718.7
A13: =A12+1 -> 11 | B13: 0 | C13: 0 | D13: =B13+C13 -> 0 | E13: =E12+D13 -> 4230 | F13: ='Daily toilet habits'!C12 -> 532.7 | G13: =G12+F13 -> 3044 | H13: =D13-F13 -> -532.7 | I13: =I12+H13 -> 1186
A14: =A13+1 -> 12 | B14: 0 | C14: 0 | D14: =B14+C14 -> 0 | E14: =E13+D14 -> 4230 | F14: ='Daily toilet habits'!C13 -> 761 | G14: =G13+F14 -> 3805 | H14: =D14-F14 -> -761 | I14: =I13+H14 -> 425
A15: =A14+1 -> 13 | B15: 0 | D15: =B15+C15 -> 0 | E15: =E14+D15 -> 4230 | F15: ='Daily toilet habits'!C14 -> 989.3 | G15: =G14+F15 -> 4794.3 | H15: =D15-F15 -> -989.3 | I15: =I14+H15 -> -564.3
A16: =A15+1 -> 14 | B16: 0 | D16: =B16+C16 -> 0 | E16: =E15+D16 -> 4230 | F16: ='Daily toilet habits'!C15 -> 761 | G16: =G15+F16 -> 5555.3 | H16: =D16-F16 -> -761 | I16: =I15+H16 -> -1325.3
A17: =A16+1 -> 15 | B17: 0 | D17: =B17+C17 -> 0 | E17: =E16+D17 -> 4230 | F17: ='Daily toilet habits'!C16 -> 456.6 | G17: =G16+F17 -> 6011.9 | H17: =D17-F17 -> -456.6 | I17: =I16+H17 -> -1781.9
A18: =A17+1 -> 16 | B18: 0 | D18: =B18+C18 -> 0 | E18: =E17+D18 -> 4230 | F18: ='Daily toilet habits'!C17 -> 532.7 | G18: =G17+F18 -> 6544.6 | H18: =D18-F18 -> -532.7 | I18: =I17+H18 -> -2314.6
A19: =A18+1 -> 17 | B19: 0 | D19: =B19+C19 -> 0 | E19: =E18+D19 -> 4230 | F19: ='Daily toilet habits'!C18 -> 608.8 | G19: =G18+F19 -> 7153.4 | H19: =D19-F19 -> -608.8 | I19: =I18+H19 -> -2923.4
A20: =A19+1 -> 18 | B20: 0 | D20: =B20+C20 -> 0 | E20: =E19+D20 -> 4230 | F20: ='Daily toilet habits'!C19 -> 304.4 | G20: =G19+F20 -> 7457.8 | H20: =D20-F20 -> -304.4 | I20: =I19+H20 -> -3227.8
A21: =A20+1 -> 19 | B21: 0 | D21: =B21+C21 -> 0 | E21: =E20+D21 -> 4230 | F21: ='Daily toilet habits'!C20 -> 152.2 | G21: =G20+F21 -> 7610 | H21: =D21-F21 -> -152.2 | I21: =I20+H21 -> -3380
A22: =A21+1 -> 20 | B22: 0 | D22: =B22+C22 -> 0 | E22: =E21+D22 -> 4230 | F22: 0 | G22: =G21+F22 -> 7610 | H22: =D22-F22 -> 0 | I22: =I21+H22 -> -3380
A23: =A22+1 -> 21 | B23: 846 | D23: =B23+C23 -> 846 | E23: =E22+D23 -> 5076 | F23: ='Daily toilet habits'!C27 -> 0 | G23: =G22+F23 -> 7610 | H23: =D23-F23 -> 846 | I23: =I22+H23 -> -2534
A24: =A23+1 -> 22 | B24: 846 | D24: =B24+C24 -> 846 | E24: =E23+D24 -> 5922 | F24: ='Daily toilet habits'!C28 -> 0 | G24: =G23+F24 -> 7610 | H24: =D24-F24 -> 846 | I24: =I23+H24 -> -1688
A25: =A24+1 -> 23 | B25: 846 | D25: =B25+C25 -> 846 | E25: =E24+D25 -> 6768 | F25: ='Daily toilet habits'!C29 -> 0 | G25: =G24+F25 -> 7610 | H25: =D25-F25 -> 846 | I25: =I24+H25 -> -842
A26: =A25+1 -> 24 | B26: 846 | D26: =B26+C26 -> 846 | E26: =E25+D26 -> 7614 | F26: ='Daily toilet habits'!C30 -> 0 | G26: =G25+F26 -> 7610 | H26: =D26-F26 -> 846 | I26: =I25+H26 -> 4
I27: {=MAX(ABS(I3:I26))} -> 4230

Sheet Tank Graph
A1: Treater greywater in | B1: Toilet flushing
A2: 862 | B2: 0
A3: =A2+862 -> 1724 | B3: 0
A4: =A3+862 -> 2586 | B4: 0
A5: =A4+862 -> 3448 | B5: 0
A6: =A5+862 -> 4310 | B6: 0
A7: =A6+862 -> 5172 | B7: 0
A8: =A7+862 -> 6034 | B8: 0
A9: =A8+862 -> 6896 | B9: 0
A10: =A9+862 -> 7758 | B10: 0
A11: =A10-B11 -> 7605.8 | B11: {='Weekday tank'!F8:F21} -> 152.2
A12: =A11-B12 -> 7301.4 | B12: 304.4
A13: =A12-B13 -> 6844.8 | B13: 456.6
A14: =A13-B14 -> 6159.9 | B14: 684.9
A15: =A14-B15 -> 5246.7 | B15: 913.2
A16: =A15-B16 -> 4714 | B16: 532.7
A17: =A16-B17 -> 3953 | B17: 761
A18: =A17-B18 -> 2963.7 | B18: 989.3
A19: =A18-B19 -> 2202.7 | B19: 761
A20: =A19-B20 -> 1746.1 | B20: 456.6
A21: =A20-B21 -> 1213.4 | B21: 532.7
A22: =A21-B22 -> 604.6 | B22: 608.8
A23: =A22-B23 -> 300.2 | B23: 304.4
... A25: =A24-B25 -> 148 | B25: 0

Sheet Weekend tank
B1: Intermittent supply of treated, reused greywater (different sources?) | C1: top up from mains to balance deficit for toilet flushing | F1: Water demand for toilet flushing
A2: Hour | B2: Treated Greywater flow into Tank (QRGW) (L/h) | C2: Potable water flow into Tank (QD) (L/h) | D2: Total Flow Into Tank that hour (Qin) (L/h) | E2: Cumulative flow in (L) | F2: Flow OUT of Tank that hour (Qout) (L/h) | G2: Cumulative flow out (L) | H2: Net Flow INTO tank that hour (Qin - Qout) (L/h) | I2: Cumulative NET Flow Into Tank (L/h) | J2: Level in the tank (L)
A3: 1 | B3: 0 | C3: 0 | D3: =B3+C3 -> 0 | E3: =D3 -> 0 | F3: 0 | G3: =F3 -> 0 | H3: =D3-F3 -> 0 | I3: =H3 -> 0
A4: =A3+1 -> 2 | B4: 0 | C4: 0 | D4: =B4+C4 -> 0 | E4: =E3+D4 -> 0 | F4: 0 | G4: =G3+F4 -> 0 | H4: =D4-F4 -> 0 | I4: =I3+H4 -> 0
A5: =A4+1 -> 3 | B5: 0 | C5: 0 | D5: =B5+C5 -> 0 | E5: =E4+D5 -> 0 | F5: 0 | G5: =G4+F5 -> 0 | H5: =D5-F5 -> 0 | I5: =I4+H5 -> 0
A6: =A5+1 -> 4 | B6: 0 | C6: 0 | D6: =B6+C6 -> 0 | E6: =E5+D6 -> 0 | F6: 0 | G6: =G5+F6 -> 0 | H6: =D6-F6 -> 0 | I6: =I5+H6 -> 0
A7: =A6+1 -> 5 | B7: 0 | C7: 0 | D7: =B7+C7 -> 0 | E7: =E6+D7 -> 0 | F7: 0 | G7: =G6+F7 -> 0 | H7: =D7-F7 -> 0 | I7: =I6+H7 -> 0
A8: =A7+1 -> 6 | B8: 0 | C8: 0 | D8: =B8+C8 -> 0 | E8: =E7+D8 -> 0 | F8: 0 | G8: =G7+F8 -> 0 | H8: =D8-F8 -> 0 | I8: =I7+H8 -> 0
A9: =A8+1 -> 7 | B9: 0 | C9: 0 | D9: =B9+C9 -> 0 | E9: =E8+D9 -> 0 | F9: 0 | G9: =G8+F9 -> 0 | H9: =D9-F9 -> 0 | I9: =I8+H9 -> 0
A10: =A9+1 -> 8 | B10: 0 | C10: 0 | D10: =B10+C10 -> 0 | E10: =E9+D10 -> 0 | F10: 0 | G10: =G9+F10 -> 0 | H10: =D10-F10 -> 0 | I10: =I9+H10 -> 0
A11: =A10+1 -> 9 | B11: 0 | C11: 0 | D11: =B11+C11 -> 0 | E11: =E10+D11 -> 0 | F11: 0 | G11: =G10+F11 -> 0 | H11: =D11-F11 -> 0 | I11: =I10+H11 -> 0
A12: =A11+1 -> 10 | B12: 0 | C12: 0 | D12: =B12+C12 -> 0 | E12: =E11+D12 -> 0 | F12: 0 | G12: =G11+F12 -> 0 | H12: =D12-F12 -> 0 | I12: =I11+H12 -> 0
A13: =A12+1 -> 11 | B13: 0 | C13: 0 | D13: =B13+C13 -> 0 | E13: =E12+D13 -> 0 | F13: 0 | G13: =G12+F13 -> 0 | H13: =D13-F13 -> 0 | I13: =I12+H13 -> 0
A14: =A13+1 -> 12 | B14: 0 | C14: 0 | D14: =B14+C14 -> 0 | E14: =E13+D14 -> 0 | F14: 0 | G14: =G13+F14 -> 0 | H14: =D14-F14 -> 0 | I14: =I13+H14 -> 0
A15: =A14+1 -> 13 | B15: 0 | D15: =B15+C15 -> 0 | E15: =E14+D15 -> 0 | F15: 0 | G15: =G14+F15 -> 0 | H15: =D15-F15 -> 0 | I15: =I14+H15 -> 0
A16: =A15+1 -> 14 | B16: 0 | D16: =B16+C16 -> 0 | E16: =E15+D16 -> 0 | F16: 0 | G16: =G15+F16 -> 0 | H16: =D16-F16 -> 0 | I16: =I15+H16 -> 0
A17: =A16+1 -> 15 | B17: 0 | D17: =B17+C17 -> 0 | E17: =E16+D17 -> 0 | F17: 0 | G17: =G16+F17 -> 0 | H17: =D17-F17 -> 0 | I17: =I16+H17 -> 0
A18: =A17+1 -> 16 | B18: 0 | D18: =B18+C18 -> 0 | E18: =E17+D18 -> 0 | F18: 0 | G18: =G17+F18 -> 0 | H18: =D18-F18 -> 0 | I18: =I17+H18 -> 0
A19: =A18+1 -> 17 | B19: 0 | D19: =B19+C19 -> 0 | E19: =E18+D19 -> 0 | F19: 0 | G19: =G18+F19 -> 0 | H19: =D19-F19 -> 0 | I19: =I18+H19 -> 0
A20: =A19+1 -> 18 | B20: 0 | D20: =B20+C20 -> 0 | E20: =E19+D20 -> 0 | F20: 0 | G20: =G19+F20 -> 0 | H20: =D20-F20 -> 0 | I20: =I19+H20 -> 0
A21: =A20+1 -> 19 | B21: 0 | D21: =B21+C21 -> 0 | E21: =E20+D21 -> 0 | F21: 0 | G21: =G20+F21 -> 0 | H21: =D21-F21 -> 0 | I21: =I20+H21 -> 0
A22: =A21+1 -> 20 | B22: 0 | D22: =B22+C22 -> 0 | E22: =E21+D22 -> 0 | F22: 0 | G22: =G21+F22 -> 0 | H22: =D22-F22 -> 0 | I22: =I21+H22 -> 0
A23: =A22+1 -> 21 | B23: 0 | D23: =B23+C23 -> 0 | E23: =E22+D23 -> 0 | F23: 0 | G23: =G22+F23 -> 0 | H23: =D23-F23 -> 0 | I23: =I22+H23 -> 0
A24: =A23+1 -> 22 | B24: 0 | D24: =B24+C24 -> 0 | E24: =E23+D24 -> 0 | F24: 0 | G24: =G23+F24 -> 0 | H24: =D24-F24 -> 0 | I24: =I23+H24 -> 0
A25: =A24+1 -> 23 | B25: 0 | D25: =B25+C25 -> 0 | E25: =E24+D25 -> 0 | F25: 0 | G25: =G24+F25 -> 0 | H25: =D25-F25 -> 0 | I25: =I24+H25 -> 0
A26: =A25+1 -> 24 | B26: 0 | D26: =B26+C26 -> 0 | E26: =E25+D26 -> 0 | F26: 0 | G26: =G25+F26 -> 0 | H26: =D26-F26 -> 0 | I26: =I25+H26 -> 0
I27: {=MAX(ABS(I3:I26))} -> 0

Sheet test
A1: =((6*1)*('Totals average weekday'!B2+'Totals average weekday'!B8+'Totals average weekday'!B10+14))+(((4*2)+(6*1))*('Totals average weekday'!B3+'Totals average weekday'!B9+'Totals average weekday'!B11))+((4*2)*'Totals average weekday'!B5+14) -> 7198

Sheet User usage
A1: User type | B1: l/day
A2: Male Researcher
A3: Female researcher
A4: Male Student
A5: Female Student
A6: Male visitor
A7: Female visitor
A8: Male Nurse
A9: Female Nurse

Sheet weekend usage

Sheet Holiday usage
